Workbook

Sheet Entradas
A1: ENTRADA DE MATERIAL
A2: CODIGO DE MATERIAL | B2: DATA DE ENTRADA | C2: QDE. | D2: NSD | E2: Coluna5 | F2: QTD.ATUAL | G2: CODIGO EQUIVALENTE | H2: LOCAL
A3: 100C09C200 | B3: 05/12/2024 - AJUSTE | C3: 6 | E3: =IF(ISBLANK(A3),"",C3*D3) -> 0 | F3: =IF(ISERROR(VLOOKUP(A3,'Controle de Estoque'!A:I,1,FALSE)),"",VLOOKUP(A3,'Controle de Estoque'!A:I,4,FALSE)) -> 6 | G3: =IF(ISBLANK(A3),"",IF(ISERROR(VLOOKUP(A3,'Controle de Estoque'!A:I,1,FALSE)),"Produto não cadastrado",VLOOKUP(A3,'Controle de Estoque'!A:I,2,FALSE))) -> 100C09C200 | H3: =IF(ISERROR(VLOOKUP(A3,'Controle de Estoque'!A:I,1,FALSE)),"",VLOOKUP(A3,'Controle de Estoque'!A:I,3,FALSE)) -> F 34
A4: 100C09EJ10 | B4: 05/12/2024 - AJUSTE | C4: 0 | E4: =IF(ISBLANK(A4),"",C4*D4) -> 0 | F4: =IF(ISERROR(VLOOKUP(A4,'Controle de Estoque'!A:I,1,FALSE)),"",VLOOKUP(A4,'Controle de Estoque'!A:I,4,FALSE)) -> 0 | G4: =IF(ISBLANK(A4),"",IF(ISERROR(VLOOKUP(A4,'Controle de Estoque'!A:I,1,FALSE)),"Produto não cadastrado",VLOOKUP(A4,'Controle de Estoque'!A:I,2,FALSE))) -> 100C09EJ10 | H4: =IF(ISERROR(VLOOKUP(A4,'Controle de Estoque'!A:I,1,FALSE)),"",VLOOKUP(A4,'Controle de Estoque'!A:I,3,FALSE)) -> F 34
A5: 100C16DJ10 | B5: 05/12/2024 - AJUSTE | C5: 0 | E5: =IF(ISBLANK(A5),"",C5*D5) -> 0 | F5: =IF(ISERROR(VLOOKUP(A5,'Controle de Estoque'!A:I,1,FALSE)),"",VLOOKUP(A5,'Controle de Estoque'!A:I,4,FALSE)) -> 0 | G5: =IF(ISBLANK(A5),"",IF(ISERROR(VLOOKUP(A5,'Controle de Estoque'!A:I,1,FALSE)),"Produto não cadastrado",VLOOKUP(A5,'Controle de Estoque'!A:I,2,FALSE))) -> 100C16DJ10 | H5: =IF(ISERROR(VLOOKUP(A5,'Controle de Estoque'!A:I,1,FALSE)),"",VLOOKUP(A5,'Controle de Estoque'!A:I,3,FALSE)) -> F 34
A6: 100C23D10 | B6: 05/12/2024 - AJUSTE | C6: 1 | E6: =IF(ISBLANK(A6),"",C6*D6) -> 0 | F6: =IF(ISERROR(VLOOKUP(A6,'Controle de Estoque'!A:I,1,FALSE)),"",VLOOKUP(A6,'Controle de Estoque'!A:I,4,FALSE)) -> 1 | G6: =IF(ISBLANK(A6),"",IF(ISERROR(VLOOKUP(A6,'Controle de Estoque'!A:I,1,FALSE)),"Produto não cadastrado",VLOOKUP(A6,'Controle de Estoque'!A:I,2,FALSE))) -> 100C23D10 | H6: =IF(ISERROR(VLOOKUP(A6,'Controle de Estoque'!A:I,1,FALSE)),"",VLOOKUP(A6,'Controle de Estoque'!A:I,3,FALSE)) -> F
A7: 100C23DJ10 | B7: 05/12/2024 - AJUSTE | C7: 3 | E7: =IF(ISBLANK(A7),"",C7*D7) -> 0 | F7: =IF(ISERROR(VLOOKUP(A7,'Controle de Estoque'!A:I,1,FALSE)),"",VLOOKUP(A7,'Controle de Estoque'!A:I,4,FALSE)) -> 3 | G7: =IF(ISBLANK(A7),"",IF(ISERROR(VLOOKUP(A7,'Controle de Estoque'!A:I,1,FALSE)),"Produto não cadastrado",VLOOKUP(A7,'Controle de Estoque'!A:I,2,FALSE))) -> 100C23DJ10 | H7: =IF(ISERROR(VLOOKUP(A7,'Controle de Estoque'!A:I,1,FALSE)),"",VLOOKUP(A7,'Controle de Estoque'!A:I,3,FALSE)) -> F 34
A8: 100C23EJ10 | B8: 05/12/2024 - AJUSTE | C8: 0 | E8: =IF(ISBLANK(A8),"",C8*D8) -> 0 | F8: =IF(ISERROR(VLOOKUP(A8,'Controle de Estoque'!A:I,1,FALSE)),"",VLOOKUP(A8,'Controle de Estoque'!A:I,4,FALSE)) -> 0 | G8: =IF(ISBLANK(A8),"",IF(ISERROR(VLOOKUP(A8,'Controle de Estoque'!A:I,1,FALSE)),"Produto não cadastrado",VLOOKUP(A8,'Controle de Estoque'!A:I,2,FALSE))) -> 100C23EJ10 | H8: =IF(ISERROR(VLOOKUP(A8,'Controle de Estoque'!A:I,1,FALSE)),"",VLOOKUP(A8,'Controle de Estoque'!A:I,3,FALSE)) -> F 34
A9: 100C23ZJ10 | B9: 05/12/2024 - AJUSTE | C9: 6 | E9: =IF(ISBLANK(A9),"",C9*D9) -> 0 | F9: =IF(ISERROR(VLOOKUP(A9,'Controle de Estoque'!A:I,1,FALSE)),"",VLOOKUP(A9,'Controle de Estoque'!A:I,4,FALSE)) -> 6 | G9: =IF(ISBLANK(A9),"",IF(ISERROR(VLOOKUP(A9,'Controle de Estoque'!A:I,1,FALSE)),"Produto não cadastrado",VLOOKUP(A9,'Controle de Estoque'!A:I,2,FALSE))) -> 100C23ZJ10 | H9: =IF(ISERROR(VLOOKUP(A9,'Controle de Estoque'!A:I,1,FALSE)),"",VLOOKUP(A9,'Controle de Estoque'!A:I,3,FALSE)) -> F 34
A10: 100C30D10 | B10: 05/12/2024 - AJUSTE | C10: 1 | E10: =IF(ISBLANK(A10),"",C10*D10) -> 0 | F10: =IF(ISERROR(VLOOKUP(A10,'Controle de Estoque'!A:I,1,FALSE)),"",VLOOKUP(A10,'Controle de Estoque'!A:I,4,FALSE)) -> 1 | G10: =IF(ISBLANK(A10),"",IF(ISERROR(VLOOKUP(A10,'Controle de Estoque'!A:I,1,FALSE)),"Produto não cadastrado",VLOOKUP(A10,'Controle de Estoque'!A:I,2,FALSE))) -> 100C30D10 | H10: =IF(ISERROR(VLOOKUP(A10,'Controle de Estoque'!A:I,1,FALSE)),"",VLOOKUP(A10,'Controle de Estoque'!A:I,3,FALSE)) -> F
A11: 100C30DJ10 | B11: 05/12/2024 - AJUSTE | C11: 1 | E11: =IF(ISBLANK(A11),"",C11*D11) -> 0 | F11: =IF(ISERROR(VLOOKUP(A11,'Controle de Estoque'!A:I,1,FALSE)),"",VLOOKUP(A11,'Controle de Estoque'!A:I,4,FALSE)) -> 1 | G11: =IF(ISBLANK(A11),"",IF(ISERROR(VLOOKUP(A11,'Controle de Estoque'!A:I,1,FALSE)),"Produto não cadastrado",VLOOKUP(A11,'Controle de Estoque'!A:I,2,FALSE))) -> 100C30DJ10 | H11: =IF(ISERROR(VLOOKUP(A11,'Controle de Estoque'!A:I,1,FALSE)),"",VLOOKUP(A11,'Controle de Estoque'!A:I,3,FALSE)) -> F 34
A12: 100C37DJ10 | B12: 05/12/2024 - AJUSTE | C12: 1 | E12: =IF(ISBLANK(A12),"",C12*D12) -> 0 | F12: =IF(ISERROR(VLOOKUP(A12,'Controle de Estoque'!A:I,1,FALSE)),"",VLOOKUP(A12,'Controle de Estoque'!A:I,4,FALSE)) -> 1 | G12: =IF(ISBLANK(A12),"",IF(ISERROR(VLOOKUP(A12,'Controle de Estoque'!A:I,1,FALSE)),"Produto não cadastrado",VLOOKUP(A12,'Controle de Estoque'!A:I,2,FALSE))) -> 100C37DJ10 | H12: =IF(ISERROR(VLOOKUP(A12,'Controle de Estoque'!A:I,1,FALSE)),"",VLOOKUP(A12,'Controle de Estoque'!A:I,3,FALSE)) -> F 34
A13: 100C43D00 | B13: 05/12/2024 - AJUSTE | C13: 0 | E13: =IF(ISBLANK(A13),"",C13*D13) -> 0 | F13: =IF(ISERROR(VLOOKUP(A13,'Controle de Estoque'!A:I,1,FALSE)),"",VLOOKUP(A13,'Controle de Estoque'!A:I,4,FALSE)) -> 0 | G13: =IF(ISBLANK(A13),"",IF(ISERROR(VLOOKUP(A13,'Controle de Estoque'!A:I,1,FALSE)),"Produto não cadastrado",VLOOKUP(A13,'Controle de Estoque'!A:I,2,FALSE))) -> 100C43D00 | H13: =IF(ISERROR(VLOOKUP(A13,'Controle de Estoque'!A:I,1,FALSE)),"",VLOOKUP(A13,'Controle de Estoque'!A:I,3,FALSE)) -> F 34
A14: 100C72KF00 | B14: 05/12/2024 - AJUSTE | C14: 0 | E14: =IF(ISBLANK(A14),"",C14*D14) -> 0 | F14: =IF(ISERROR(VLOOKUP(A14,'Controle de Estoque'!A:I,1,FALSE)),"",VLOOKUP(A14,'Controle de Estoque'!A:I,4,FALSE)) -> 0 | G14: =IF(ISBLANK(A14),"",IF(ISERROR(VLOOKUP(A14,'Controle de Estoque'!A:I,1,FALSE)),"Produto não cadastrado",VLOOKUP(A14,'Controle de Estoque'!A:I,2,FALSE))) -> 100C72KF00 | H14: =IF(ISERROR(VLOOKUP(A14,'Controle de Estoque'!A:I,1,FALSE)),"",VLOOKUP(A14,'Controle de Estoque'!A:I,3,FALSE)) -> F 34
... A273: 1606XLRED40 | B273: 05/12/2024 - AJUSTE | C273: 1 | E273: =IF(ISBLANK(A273),"",C273*D273) -> 0 | F273: =IF(ISERROR(VLOOKUP(A273,'Controle de Estoque'!A:I,1,FALSE)),"",VLOOKUP(A273,'Controle de Estoque'!A:I,4,FALSE)) -> 1 | G273: =IF(ISBLANK(A273),"",IF(ISERROR(VLOOKUP(A273,'Controle de Estoque'!A:I,1,FALSE)),"Produto não cadastrado",VLOOKUP(A273,'Controle de Estoque'!A:I,2,FALSE))) -> 1606XLRED40 | H273: =IF(ISERROR(VLOOKUP(A273,'Controle de Estoque'!A:I,1,FALSE)),"",VLOOKUP(A273,'Controle de Estoque'!A:I,3,FALSE)) -> F 14
A274: 1606XLS120E | B274: 05/12/2024 - AJUSTE | C274: 0 | D274: CERTO | E274: =IF(ISBLANK(A274),"",C274*D274) -> #VALUE! | F274: =IF(ISERROR(VLOOKUP(A274,'Controle de Estoque'!A:I,1,FALSE)),"",VLOOKUP(A274,'Controle de Estoque'!A:I,4,FALSE)) -> 0 | G274: =IF(ISBLANK(A274),"",IF(ISERROR(VLOOKUP(A274,'Controle de Estoque'!A:I,1,FALSE)),"Produto não cadastrado",VLOOKUP(A274,'Controle de Estoque'!A:I,2,FALSE))) -> 1606XLS120E | H274: =IF(ISERROR(VLOOKUP(A274,'Controle de Estoque'!A:I,1,FALSE)),"",VLOOKUP(A274,'Controle de Estoque'!A:I,3,FALSE)) -> F 14
A275: 1606XLS240E | B275: 05/12/2024 - AJUSTE | C275: 0 | E275: =IF(ISBLANK(A275),"",C275*D275) -> 0 | F275: =IF(ISERROR(VLOOKUP(A275,'Controle de Estoque'!A:I,1,FALSE)),"",VLOOKUP(A275,'Controle de Estoque'!A:I,4,FALSE)) -> 0 | G275: =IF(ISBLANK(A275),"",IF(ISERROR(VLOOKUP(A275,'Controle de Estoque'!A:I,1,FALSE)),"Produto não cadastrado",VLOOKUP(A275,'Controle de Estoque'!A:I,2,FALSE))) -> 1606XLS240E | H275: =IF(ISERROR(VLOOKUP(A275,'Controle de Estoque'!A:I,1,FALSE)),"",VLOOKUP(A275,'Controle de Estoque'!A:I,3,FALSE)) -> F 14
A276: 1606XLS480E3 | B276: 05/12/2024 - AJUSTE | C276: 0 | E276: =IF(ISBLANK(A276),"",C276*D276) -> 0 | F276: =IF(ISERROR(VLOOKUP(A276,'Controle de Estoque'!A:I,1,FALSE)),"",VLOOKUP(A276,'Controle de Estoque'!A:I,4,FALSE)) -> 0 | G276: =IF(ISBLANK(A276),"",IF(ISERROR(VLOOKUP(A276,'Controle de Estoque'!A:I,1,FALSE)),"Produto não cadastrado",VLOOKUP(A276,'Controle de Estoque'!A:I,2,FALSE))) -> 1606XLS480E3 | H276: =IF(ISERROR(VLOOKUP(A276,'Controle de Estoque'!A:I,1,FALSE)),"",VLOOKUP(A276,'Controle de Estoque'!A:I,3,FALSE)) -> F 14
A277: 1609U500E | B277: 05/12/2024 - AJUSTE | C277: 0 | E277: =IF(ISBLANK(A277),"",C277*D277) -> 0 | F277: =IF(ISERROR(VLOOKUP(A277,'Controle de Estoque'!A:I,1,FALSE)),"",VLOOKUP(A277,'Controle de Estoque'!A:I,4,FALSE)) -> 0 | G277: =IF(ISBLANK(A277),"",IF(ISERROR(VLOOKUP(A277,'Controle de Estoque'!A:I,1,FALSE)),"Produto não cadastrado",VLOOKUP(A277,'Controle de Estoque'!A:I,2,FALSE))) -> 1609U500E | H277: =IF(ISERROR(VLOOKUP(A277,'Controle de Estoque'!A:I,1,FALSE)),"",VLOOKUP(A277,'Controle de Estoque'!A:I,3,FALSE)) -> F
A278: 160DN2 | B278: 05/12/2024 - AJUSTE | C278: 1 | E278: =IF(ISBLANK(A278),"",C278*D278) -> 0 | F278: =IF(ISERROR(VLOOKUP(A278,'Controle de Estoque'!A:I,1,FALSE)),"",VLOOKUP(A278,'Controle de Estoque'!A:I,4,FALSE)) -> 1 | G278: =IF(ISBLANK(A278),"",IF(ISERROR(VLOOKUP(A278,'Controle de Estoque'!A:I,1,FALSE)),"Produto não cadastrado",VLOOKUP(A278,'Controle de Estoque'!A:I,2,FALSE))) -> 160DN2 | H278: =IF(ISERROR(VLOOKUP(A278,'Controle de Estoque'!A:I,1,FALSE)),"",VLOOKUP(A278,'Controle de Estoque'!A:I,3,FALSE)) -> F
A279: 165LTTM5TM5 | B279: 05/12/2024 - AJUSTE | C279: 18 | E279: =IF(ISBLANK(A279),"",C279*D279) -> 0 | F279: =IF(ISERROR(VLOOKUP(A279,'Controle de Estoque'!A:I,1,FALSE)),"",VLOOKUP(A279,'Controle de Estoque'!A:I,4,FALSE)) -> 18 | G279: =IF(ISBLANK(A279),"",IF(ISERROR(VLOOKUP(A279,'Controle de Estoque'!A:I,1,FALSE)),"Produto não cadastrado",VLOOKUP(A279,'Controle de Estoque'!A:I,2,FALSE))) -> 1SNA216110R2200 | H279: =IF(ISERROR(VLOOKUP(A279,'Controle de Estoque'!A:I,1,FALSE)),"",VLOOKUP(A279,'Controle de Estoque'!A:I,3,FALSE)) -> N/A
A280: 1694-PFA1244 | B280: 05/12/2024 - AJUSTE | C280: 5 | E280: =IF(ISBLANK(A280),"",C280*D280) -> 0 | F280: =IF(ISERROR(VLOOKUP(A280,'Controle de Estoque'!A:I,1,FALSE)),"",VLOOKUP(A280,'Controle de Estoque'!A:I,4,FALSE)) -> 5 | G280: =IF(ISBLANK(A280),"",IF(ISERROR(VLOOKUP(A280,'Controle de Estoque'!A:I,1,FALSE)),"Produto não cadastrado",VLOOKUP(A280,'Controle de Estoque'!A:I,2,FALSE))) -> 1694-PFA1244 | H280: =IF(ISERROR(VLOOKUP(A280,'Controle de Estoque'!A:I,1,FALSE)),"",VLOOKUP(A280,'Controle de Estoque'!A:I,3,FALSE)) -> F
A281: 16NHG000B690 | B281: 05/12/2024 - AJUSTE | C281: 2 | E281: =IF(ISBLANK(A281),"",C281*D281) -> 0 | F281: =IF(ISERROR(VLOOKUP(A281,'Controle de Estoque'!A:I,1,FALSE)),"",VLOOKUP(A281,'Controle de Estoque'!A:I,4,FALSE)) -> 2 | G281: =IF(ISBLANK(A281),"",IF(ISERROR(VLOOKUP(A281,'Controle de Estoque'!A:I,1,FALSE)),"Produto não cadastrado",VLOOKUP(A281,'Controle de Estoque'!A:I,2,FALSE))) -> 16NHG000B690 | H281: =IF(ISERROR(VLOOKUP(A281,'Controle de Estoque'!A:I,1,FALSE)),"",VLOOKUP(A281,'Controle de Estoque'!A:I,3,FALSE)) -> N/A
A282: 170M1518 | B282: 05/12/2024 - AJUSTE | C282: 1 | E282: =IF(ISBLANK(A282),"",C282*D282) -> 0 | F282: =IF(ISERROR(VLOOKUP(A282,'Controle de Estoque'!A:I,1,FALSE)),"",VLOOKUP(A282,'Controle de Estoque'!A:I,4,FALSE)) -> 1 | G282: =IF(ISBLANK(A282),"",IF(ISERROR(VLOOKUP(A282,'Controle de Estoque'!A:I,1,FALSE)),"Produto não cadastrado",VLOOKUP(A282,'Controle de Estoque'!A:I,2,FALSE))) -> 170M1518 | H282: =IF(ISERROR(VLOOKUP(A282,'Controle de Estoque'!A:I,1,FALSE)),"",VLOOKUP(A282,'Controle de Estoque'!A:I,3,FALSE)) -> N/A
A283: 170M1558ABB | B283: 05/12/2024 - AJUSTE | C283: 0 | E283: =IF(ISBLANK(A283),"",C283*D283) -> 0 | F283: =IF(ISERROR(VLOOKUP(A283,'Controle de Estoque'!A:I,1,FALSE)),"",VLOOKUP(A283,'Controle de Estoque'!A:I,4,FALSE)) -> 0 | G283: =IF(ISBLANK(A283),"",IF(ISERROR(VLOOKUP(A283,'Controle de Estoque'!A:I,1,FALSE)),"Produto não cadastrado",VLOOKUP(A283,'Controle de Estoque'!A:I,2,FALSE))) -> 1SCA080880R1001 | H283: =IF(ISERROR(VLOOKUP(A283,'Controle de Estoque'!A:I,1,FALSE)),"",VLOOKUP(A283,'Controle de Estoque'!A:I,3,FALSE)) -> D 26
A284: 170M1560ABB | B284: 05/12/2024 - AJUSTE | C284: 0 | E284: =IF(ISBLANK(A284),"",C284*D284) -> 0 | F284: =IF(ISERROR(VLOOKUP(A284,'Controle de Estoque'!A:I,1,FALSE)),"",VLOOKUP(A284,'Controle de Estoque'!A:I,4,FALSE)) -> 0 | G284: =IF(ISBLANK(A284),"",IF(ISERROR(VLOOKUP(A284,'Controle de Estoque'!A:I,1,FALSE)),"Produto não cadastrado",VLOOKUP(A284,'Controle de Estoque'!A:I,2,FALSE))) -> 1SCA080882R1001 | H284: =IF(ISERROR(VLOOKUP(A284,'Controle de Estoque'!A:I,1,FALSE)),"",VLOOKUP(A284,'Controle de Estoque'!A:I,3,FALSE)) -> D 26
A285: 170M1561ABB | B285: 05/12/2024 - AJUSTE | C285: 0 | E285: =IF(ISBLANK(A285),"",C285*D285) -> 0 | F285: =IF(ISERROR(VLOOKUP(A285,'Controle de Estoque'!A:I,1,FALSE)),"",VLOOKUP(A285,'Controle de Estoque'!A:I,4,FALSE)) -> 3 | G285: =IF(ISBLANK(A285),"",IF(ISERROR(VLOOKUP(A285,'Controle de Estoque'!A:I,1,FALSE)),"Produto não cadastrado",VLOOKUP(A285,'Controle de Estoque'!A:I,2,FALSE))) -> 1SCA080883R1001 | H285: =IF(ISERROR(VLOOKUP(A285,'Controle de Estoque'!A:I,1,FALSE)),"",VLOOKUP(A285,'Controle de Estoque'!A:I,3,FALSE)) -> D 26
A286: 170M1562ABB | B286: 05/12/2024 - AJUSTE | C286: 1 | E286: =IF(ISBLANK(A286),"",C286*D286) -> 0 | F286: =IF(ISERROR(VLOOKUP(A286,'Controle de Estoque'!A:I,1,FALSE)),"",VLOOKUP(A286,'Controle de Estoque'!A:I,4,FALSE)) -> 1 | G286: =IF(ISBLANK(A286),"",IF(ISERROR(VLOOKUP(A286,'Controle de Estoque'!A:I,1,FALSE)),"Produto não cadastrado",VLOOKUP(A286,'Controle de Estoque'!A:I,2,FALSE))) -> 1SCA080884R1001 | H286: =IF(ISERROR(VLOOKUP(A286,'Controle de Estoque'!A:I,1,FALSE)),"",VLOOKUP(A286,'Controle de Estoque'!A:I,3,FALSE)) -> D 26
... A288: 170M1564ABB | B288: 05/12/2024 - AJUSTE | C288: 0 | E288: =IF(ISBLANK(A288),"",C288*D288) -> 0 | F288: =IF(ISERROR(VLOOKUP(A288,'Controle de Estoque'!A:I,1,FALSE)),"",VLOOKUP(A288,'Controle de Estoque'!A:I,4,FALSE)) -> 0 | G288: =IF(ISBLANK(A288),"",IF(ISERROR(VLOOKUP(A288,'Controle de Estoque'!A:I,1,FALSE)),"Produto não cadastrado",VLOOKUP(A288,'Controle de Estoque'!A:I,2,FALSE))) -> 1SCA080886R1001 | H288: =IF(ISERROR(VLOOKUP(A288,'Controle de Estoque'!A:I,1,FALSE)),"",VLOOKUP(A288,'Controle de Estoque'!A:I,3,FALSE)) -> D 26
A289: 170M1565ABB | B289: 05/12/2024 - AJUSTE | C289: 18 | D289: CERTO | E289: =IF(ISBLANK(A289),"",C289*D289) -> #VALUE! | F289: =IF(ISERROR(VLOOKUP(A289,'Controle de Estoque'!A:I,1,FALSE)),"",VLOOKUP(A289,'Controle de Estoque'!A:I,4,FALSE)) -> 15 | G289: =IF(ISBLANK(A289),"",IF(ISERROR(VLOOKUP(A289,'Controle de Estoque'!A:I,1,FALSE)),"Produto não cadastrado",VLOOKUP(A289,'Controle de Estoque'!A:I,2,FALSE))) -> 1SCA080887R1001 | H289: =IF(ISERROR(VLOOKUP(A289,'Controle de Estoque'!A:I,1,FALSE)),"",VLOOKUP(A289,'Controle de Estoque'!A:I,3,FALSE)) -> D 20
A290: 170M1566ABB | B290: 05/12/2024 - AJUSTE | C290: 6 | E290: =IF(ISBLANK(A290),"",C290*D290) -> 0 | F290: =IF(ISERROR(VLOOKUP(A290,'Controle de Estoque'!A:I,1,FALSE)),"",VLOOKUP(A290,'Controle de Estoque'!A:I,4,FALSE)) -> 3 | G290: =IF(ISBLANK(A290),"",IF(ISERROR(VLOOKUP(A290,'Controle de Estoque'!A:I,1,FALSE)),"Produto não cadastrado",VLOOKUP(A290,'Controle de Estoque'!A:I,2,FALSE))) -> 1SCA080888R1001 | H290: =IF(ISERROR(VLOOKUP(A290,'Controle de Estoque'!A:I,1,FALSE)),"",VLOOKUP(A290,'Controle de Estoque'!A:I,3,FALSE)) -> D 26
A291: 170M1567ABB | B291: 05/12/2024 - AJUSTE | C291: 0 | E291: =IF(ISBLANK(A291),"",C291*D291) -> 0 | F291: =IF(ISERROR(VLOOKUP(A291,'Controle de Estoque'!A:I,1,FALSE)),"",VLOOKUP(A291,'Controle de Estoque'!A:I,4,FALSE)) -> 0 | G291: =IF(ISBLANK(A291),"",IF(ISERROR(VLOOKUP(A291,'Controle de Estoque'!A:I,1,FALSE)),"Produto não cadastrado",VLOOKUP(A291,'Controle de Estoque'!A:I,2,FALSE))) -> 1SCA080889R1001 | H291: =IF(ISERROR(VLOOKUP(A291,'Controle de Estoque'!A:I,1,FALSE)),"",VLOOKUP(A291,'Controle de Estoque'!A:I,3,FALSE)) -> D 26
A292: 170M1568ABB | B292: 05/12/2024 - AJUSTE | C292: 0 | E292: =IF(ISBLANK(A292),"",C292*D292) -> 0 | F292: =IF(ISERROR(VLOOKUP(A292,'Controle de Estoque'!A:I,1,FALSE)),"",VLOOKUP(A292,'Controle de Estoque'!A:I,4,FALSE)) -> 3 | G292: =IF(ISBLANK(A292),"",IF(ISERROR(VLOOKUP(A292,'Controle de Estoque'!A:I,1,FALSE)),"Produto não cadastrado",VLOOKUP(A292,'Controle de Estoque'!A:I,2,FALSE))) -> 1SCA080890R1001 | H292: =IF(ISERROR(VLOOKUP(A292,'Controle de Estoque'!A:I,1,FALSE)),"",VLOOKUP(A292,'Controle de Estoque'!A:I,3,FALSE)) -> D 26
A293: 170M1569ABB | B293: 05/12/2024 - AJUSTE | C293: 12 | E293: =IF(ISBLANK(A293),"",C293*D293) -> 0 | F293: =IF(ISERROR(VLOOKUP(A293,'Controle de Estoque'!A:I,1,FALSE)),"",VLOOKUP(A293,'Controle de Estoque'!A:I,4,FALSE)) -> 12 | G293: =IF(ISBLANK(A293),"",IF(ISERROR(VLOOKUP(A293,'Controle de Estoque'!A:I,1,FALSE)),"Produto não cadastrado",VLOOKUP(A293,'Controle de Estoque'!A:I,2,FALSE))) -> 1SCA080891R1001 | H293: =IF(ISERROR(VLOOKUP(A293,'Controle de Estoque'!A:I,1,FALSE)),"",VLOOKUP(A293,'Controle de Estoque'!A:I,3,FALSE)) -> D 26
A294: 170M1570ABB | B294: 05/12/2024 - AJUSTE | C294: 6 | E294: =IF(ISBLANK(A294),"",C294*D294) -> 0 | F294: =IF(ISERROR(VLOOKUP(A294,'Controle de Estoque'!A:I,1,FALSE)),"",VLOOKUP(A294,'Controle de Estoque'!A:I,4,FALSE)) -> 5 | G294: =IF(ISBLANK(A294),"",IF(ISERROR(VLOOKUP(A294,'Controle de Estoque'!A:I,1,FALSE)),"Produto não cadastrado",VLOOKUP(A294,'Controle de Estoque'!A:I,2,FALSE))) -> 1SCA080892R1001 | H294: =IF(ISERROR(VLOOKUP(A294,'Controle de Estoque'!A:I,1,FALSE)),"",VLOOKUP(A294,'Controle de Estoque'!A:I,3,FALSE)) -> D 26
A295: 170M1572ABB | B295: 05/12/2024 - AJUSTE | C295: 0 | E295: =IF(ISBLANK(A295),"",C295*D295) -> 0 | F295: =IF(ISERROR(VLOOKUP(A295,'Controle de Estoque'!A:I,1,FALSE)),"",VLOOKUP(A295,'Controle de Estoque'!A:I,4,FALSE)) -> 0 | G295: =IF(ISBLANK(A295),"",IF(ISERROR(VLOOKUP(A295,'Controle de Estoque'!A:I,1,FALSE)),"Produto não cadastrado",VLOOKUP(A295,'Controle de Estoque'!A:I,2,FALSE))) -> 1SCA080894R1001 | H295: =IF(ISERROR(VLOOKUP(A295,'Controle de Estoque'!A:I,1,FALSE)),"",VLOOKUP(A295,'Controle de Estoque'!A:I,3,FALSE)) -> D 26
A296: 170M3813 | B296: 05/12/2024 - AJUSTE | C296: 6 | E296: =IF(ISBLANK(A296),"",C296*D296) -> 0 | F296: =IF(ISERROR(VLOOKUP(A296,'Controle de Estoque'!A:I,1,FALSE)),"",VLOOKUP(A296,'Controle de Estoque'!A:I,4,FALSE)) -> 6 | G296: =IF(ISBLANK(A296),"",IF(ISERROR(VLOOKUP(A296,'Controle de Estoque'!A:I,1,FALSE)),"Produto não cadastrado",VLOOKUP(A296,'Controle de Estoque'!A:I,2,FALSE))) -> 170M3813 | H296: =IF(ISERROR(VLOOKUP(A296,'Controle de Estoque'!A:I,1,FALSE)),"",VLOOKUP(A296,'Controle de Estoque'!A:I,3,FALSE)) -> D 26
A297: 170M3814ABB | B297: 05/12/2024 - AJUSTE | C297: 6 | D297: CERTO | E297: =IF(ISBLANK(A297),"",C297*D297) -> #VALUE! | F297: =IF(ISERROR(VLOOKUP(A297,'Controle de Estoque'!A:I,1,FALSE)),"",VLOOKUP(A297,'Controle de Estoque'!A:I,4,FALSE)) -> 6 | G297: =IF(ISBLANK(A297),"",IF(ISERROR(VLOOKUP(A297,'Controle de Estoque'!A:I,1,FALSE)),"Produto não cadastrado",VLOOKUP(A297,'Controle de Estoque'!A:I,2,FALSE))) -> 170M3814ABB | H297: =IF(ISERROR(VLOOKUP(A297,'Controle de Estoque'!A:I,1,FALSE)),"",VLOOKUP(A297,'Controle de Estoque'!A:I,3,FALSE)) -> N/A
A298: 170M3816ABB | B298: 05/12/2024 - AJUSTE | C298: 6 | E298: =IF(ISBLANK(A298),"",C298*D298) -> 0 | F298: =IF(ISERROR(VLOOKUP(A298,'Controle de Estoque'!A:I,1,FALSE)),"",VLOOKUP(A298,'Controle de Estoque'!A:I,4,FALSE)) -> 5 | G298: =IF(ISBLANK(A298),"",IF(ISERROR(VLOOKUP(A298,'Controle de Estoque'!A:I,1,FALSE)),"Produto não cadastrado",VLOOKUP(A298,'Controle de Estoque'!A:I,2,FALSE))) -> 1SCA080902R1001 | H298: =IF(ISERROR(VLOOKUP(A298,'Controle de Estoque'!A:I,1,FALSE)),"",VLOOKUP(A298,'Controle de Estoque'!A:I,3,FALSE)) -> D 26
A299: 170M3817ABB | B299: 05/12/2024 - AJUSTE | C299: 2 | E299: =IF(ISBLANK(A299),"",C299*D299) -> 0 | F299: =IF(ISERROR(VLOOKUP(A299,'Controle de Estoque'!A:I,1,FALSE)),"",VLOOKUP(A299,'Controle de Estoque'!A:I,4,FALSE)) -> 2 | G299: =IF(ISBLANK(A299),"",IF(ISERROR(VLOOKUP(A299,'Controle de Estoque'!A:I,1,FALSE)),"Produto não cadastrado",VLOOKUP(A299,'Controle de Estoque'!A:I,2,FALSE))) -> 1SCA080903R1001 | H299: =IF(ISERROR(VLOOKUP(A299,'Controle de Estoque'!A:I,1,FALSE)),"",VLOOKUP(A299,'Controle de Estoque'!A:I,3,FALSE)) -> D 26
...

Sheet Controle de Estoque
A1: CONTROLE DE ESTOQUE
A2: CONTROLE DE ESTOQUE
A3: CODIGO | B3: CODIGO EQUIVALENTE | C3: LOCALIZAÇÃO | D3: QUANTIDADE | F3: FORNECEDOR | G3: FAMILIA | H3: OBSER | K3: ENTRADA | L3: SAIDA
A4: CODIGO | B4: CODIGO EQUIVALENTE | C4: LOCALIZAÇAO | D4: QUANTIDADE | E4: QTD | F4: FORNECEDOR | G4: FAMILIA | H4: OBSER | I4: Coluna9 | J4: DESCRICAO | K4: ENTRADA | L4: SAIDA | M4: O
A5: 63998931 | B5: 63998931 | C5: ARMARIO 02 | D5: =IF(ISBLANK($D$2),SUMIFS(Entradas!$C:$C,Entradas!$A:$A,$A5)-SUMIFS(SAIDA!$C:$C,SAIDA!$A:$A,$A5),SUMIFS(Entradas!$C:$C,Entradas!$A:$A,$A5,Entradas!$B:$B,"<="&$D$2)-SUMIFS(SAIDA!$C:$C,SAIDA!$A:$A,$A5,SAIDA!$B:$B,"<="&$D$2)) -> 4 | E5: =IF($A5="","",IFERROR(VLOOKUP($A5,Entradas!$A:$D,4,FALSE),"")) -> 0 | F5: ABB | K5: =SUMIF(Entradas!A:A,A5,Entradas!C:C) -> 5 | L5: =SUMIF(SAIDA!A:A,A5,SAIDA!C:C) -> 1 | M5: O
A6: 64650424 | B6: 64650424 | C6: ARMARIO 02 | D6: =IF(ISBLANK($D$2),SUMIFS(Entradas!$C:$C,Entradas!$A:$A,$A6)-SUMIFS(SAIDA!$C:$C,SAIDA!$A:$A,$A6),SUMIFS(Entradas!$C:$C,Entradas!$A:$A,$A6,Entradas!$B:$B,"<="&$D$2)-SUMIFS(SAIDA!$C:$C,SAIDA!$A:$A,$A6,SAIDA!$B:$B,"<="&$D$2)) -> 1 | E6: =IF($A6="","",IFERROR(VLOOKUP($A6,Entradas!$A:$D,4,FALSE),"")) | F6: ABB | K6: =SUMIF(Entradas!A:A,A6,Entradas!C:C) -> 2 | L6: =SUMIF(SAIDA!A:A,A6,SAIDA!C:C) -> 1
A7: 68257662 | B7: 68257662 | C7: ARMARIO 01 | D7: =IF(ISBLANK($D$2),SUMIFS(Entradas!$C:$C,Entradas!$A:$A,$A7)-SUMIFS(SAIDA!$C:$C,SAIDA!$A:$A,$A7),SUMIFS(Entradas!$C:$C,Entradas!$A:$A,$A7,Entradas!$B:$B,"<="&$D$2)-SUMIFS(SAIDA!$C:$C,SAIDA!$A:$A,$A7,SAIDA!$B:$B,"<="&$D$2)) -> 0 | E7: =IF($A7="","",IFERROR(VLOOKUP($A7,Entradas!$A:$D,4,FALSE),"")) -> 0 | F7: ABB | K7: =SUMIF(Entradas!A:A,A7,Entradas!C:C) -> 3 | L7: =SUMIF(SAIDA!A:A,A7,SAIDA!C:C) -> 3
A8: 68569354 | C8: ARMARIO 01 | D8: =IF(ISBLANK($D$2),SUMIFS(Entradas!$C:$C,Entradas!$A:$A,$A8)-SUMIFS(SAIDA!$C:$C,SAIDA!$A:$A,$A8),SUMIFS(Entradas!$C:$C,Entradas!$A:$A,$A8,Entradas!$B:$B,"<="&$D$2)-SUMIFS(SAIDA!$C:$C,SAIDA!$A:$A,$A8,SAIDA!$B:$B,"<="&$D$2)) -> 3 | E8: =IF($A8="","",IFERROR(VLOOKUP($A8,Entradas!$A:$D,4,FALSE),"")) -> 0 | F8: ABB | K8: =SUMIF(Entradas!A:A,A8,Entradas!C:C) -> 3 | L8: =SUMIF(SAIDA!A:A,A8,SAIDA!C:C) -> 0
A9: 100C09C200 | B9: 100C09C200 | C9: F 34 | D9: =IF(ISBLANK($D$2),SUMIFS(Entradas!$C:$C,Entradas!$A:$A,$A9)-SUMIFS(SAIDA!$C:$C,SAIDA!$A:$A,$A9),SUMIFS(Entradas!$C:$C,Entradas!$A:$A,$A9,Entradas!$B:$B,"<="&$D$2)-SUMIFS(SAIDA!$C:$C,SAIDA!$A:$A,$A9,SAIDA!$B:$B,"<="&$D$2)) -> 6 | E9: =IF($A9="","",IFERROR(VLOOKUP($A9,Entradas!$A:$D,4,FALSE),"")) -> 0 | F9: ALLEN BRADLEY | I9: #N/A | K9: =SUMIF(Entradas!A:A,A9,Entradas!C:C) -> 6 | L9: =SUMIF(SAIDA!A:A,A9,SAIDA!C:C) -> 0
A10: 100C09EJ10 | B10: 100C09EJ10 | C10: F 34 | D10: =IF(ISBLANK($D$2),SUMIFS(Entradas!$C:$C,Entradas!$A:$A,$A10)-SUMIFS(SAIDA!$C:$C,SAIDA!$A:$A,$A10),SUMIFS(Entradas!$C:$C,Entradas!$A:$A,$A10,Entradas!$B:$B,"<="&$D$2)-SUMIFS(SAIDA!$C:$C,SAIDA!$A:$A,$A10,SAIDA!$B:$B,"<="&$D$2)) -> 0 | E10: =IF($A10="","",IFERROR(VLOOKUP($A10,Entradas!$A:$D,4,FALSE),"")) -> 0 | F10: ALLEN BRADLEY | I10: #N/A | K10: =SUMIF(Entradas!A:A,A10,Entradas!C:C) -> 0 | L10: =SUMIF(SAIDA!A:A,A10,SAIDA!C:C) -> 0
A11: 100C16DJ10 | B11: 100C16DJ10 | C11: F 34 | D11: =IF(ISBLANK($D$2),SUMIFS(Entradas!$C:$C,Entradas!$A:$A,$A11)-SUMIFS(SAIDA!$C:$C,SAIDA!$A:$A,$A11),SUMIFS(Entradas!$C:$C,Entradas!$A:$A,$A11,Entradas!$B:$B,"<="&$D$2)-SUMIFS(SAIDA!$C:$C,SAIDA!$A:$A,$A11,SAIDA!$B:$B,"<="&$D$2)) -> 0 | E11: =IF($A11="","",IFERROR(VLOOKUP($A11,Entradas!$A:$D,4,FALSE),"")) -> 0 | F11: ALLEN BRADLEY | H11: 1- Fora da cx. | I11: #N/A | K11: =SUMIF(Entradas!A:A,A11,Entradas!C:C) -> 0 | L11: =SUMIF(SAIDA!A:A,A11,SAIDA!C:C) -> 0
A12: 100C23D10 | B12: 100C23D10 | C12: F | D12: =IF(ISBLANK($D$2),SUMIFS(Entradas!$C:$C,Entradas!$A:$A,$A12)-SUMIFS(SAIDA!$C:$C,SAIDA!$A:$A,$A12),SUMIFS(Entradas!$C:$C,Entradas!$A:$A,$A12,Entradas!$B:$B,"<="&$D$2)-SUMIFS(SAIDA!$C:$C,SAIDA!$A:$A,$A12,SAIDA!$B:$B,"<="&$D$2)) -> 1 | E12: =IF($A12="","",IFERROR(VLOOKUP($A12,Entradas!$A:$D,4,FALSE),"")) -> 0 | F12: ALLEN BRADLEY | H12: 1- Fora da cx. | I12: #N/A | K12: =SUMIF(Entradas!A:A,A12,Entradas!C:C) -> 1 | L12: =SUMIF(SAIDA!A:A,A12,SAIDA!C:C) -> 0
A13: 100C23DJ10 | B13: 100C23DJ10 | C13: F 34 | D13: =IF(ISBLANK($D$2),SUMIFS(Entradas!$C:$C,Entradas!$A:$A,$A13)-SUMIFS(SAIDA!$C:$C,SAIDA!$A:$A,$A13),SUMIFS(Entradas!$C:$C,Entradas!$A:$A,$A13,Entradas!$B:$B,"<="&$D$2)-SUMIFS(SAIDA!$C:$C,SAIDA!$A:$A,$A13,SAIDA!$B:$B,"<="&$D$2)) -> 3 | E13: =IF($A13="","",IFERROR(VLOOKUP($A13,Entradas!$A:$D,4,FALSE),"")) -> 0 | F13: ALLEN BRADLEY | I13: #N/A | K13: =SUMIF(Entradas!A:A,A13,Entradas!C:C) -> 3 | L13: =SUMIF(SAIDA!A:A,A13,SAIDA!C:C) -> 0
A14: 100C23EJ10 | B14: 100C23EJ10 | C14: F 34 | D14: =IF(ISBLANK($D$2),SUMIFS(Entradas!$C:$C,Entradas!$A:$A,$A14)-SUMIFS(SAIDA!$C:$C,SAIDA!$A:$A,$A14),SUMIFS(Entradas!$C:$C,Entradas!$A:$A,$A14,Entradas!$B:$B,"<="&$D$2)-SUMIFS(SAIDA!$C:$C,SAIDA!$A:$A,$A14,SAIDA!$B:$B,"<="&$D$2)) -> 0 | E14: =IF($A14="","",IFERROR(VLOOKUP($A14,Entradas!$A:$D,4,FALSE),"")) -> 0 | F14: ALLEN BRADLEY | I14: #N/A | K14: =SUMIF(Entradas!A:A,A14,Entradas!C:C) -> 0 | L14: =SUMIF(SAIDA!A:A,A14,SAIDA!C:C) -> 0
A15: 100C23ZJ10 | B15: 100C23ZJ10 | C15: F 34 | D15: =IF(ISBLANK($D$2),SUMIFS(Entradas!$C:$C,Entradas!$A:$A,$A15)-SUMIFS(SAIDA!$C:$C,SAIDA!$A:$A,$A15),SUMIFS(Entradas!$C:$C,Entradas!$A:$A,$A15,Entradas!$B:$B,"<="&$D$2)-SUMIFS(SAIDA!$C:$C,SAIDA!$A:$A,$A15,SAIDA!$B:$B,"<="&$D$2)) -> 6 | E15: =IF($A15="","",IFERROR(VLOOKUP($A15,Entradas!$A:$D,4,FALSE),"")) -> 0 | F15: ALLEN BRADLEY | I15: #N/A | K15: =SUMIF(Entradas!A:A,A15,Entradas!C:C) -> 6 | L15: =SUMIF(SAIDA!A:A,A15,SAIDA!C:C) -> 0
A16: 100C30D10 | B16: 100C30D10 | C16: F | D16: =IF(ISBLANK($D$2),SUMIFS(Entradas!$C:$C,Entradas!$A:$A,$A16)-SUMIFS(SAIDA!$C:$C,SAIDA!$A:$A,$A16),SUMIFS(Entradas!$C:$C,Entradas!$A:$A,$A16,Entradas!$B:$B,"<="&$D$2)-SUMIFS(SAIDA!$C:$C,SAIDA!$A:$A,$A16,SAIDA!$B:$B,"<="&$D$2)) -> 1 | E16: =IF($A16="","",IFERROR(VLOOKUP($A16,Entradas!$A:$D,4,FALSE),"")) -> 0 | F16: ALLEN BRADLEY | I16: #N/A | K16: =SUMIF(Entradas!A:A,A16,Entradas!C:C) -> 1 | L16: =SUMIF(SAIDA!A:A,A16,SAIDA!C:C) -> 0
A17: 100C30DJ10 | B17: 100C30DJ10 | C17: F 34 | D17: =IF(ISBLANK($D$2),SUMIFS(Entradas!$C:$C,Entradas!$A:$A,$A17)-SUMIFS(SAIDA!$C:$C,SAIDA!$A:$A,$A17),SUMIFS(Entradas!$C:$C,Entradas!$A:$A,$A17,Entradas!$B:$B,"<="&$D$2)-SUMIFS(SAIDA!$C:$C,SAIDA!$A:$A,$A17,SAIDA!$B:$B,"<="&$D$2)) -> 1 | E17: =IF($A17="","",IFERROR(VLOOKUP($A17,Entradas!$A:$D,4,FALSE),"")) -> 0 | F17: ALLEN BRADLEY | I17: #N/A | K17: =SUMIF(Entradas!A:A,A17,Entradas!C:C) -> 1 | L17: =SUMIF(SAIDA!A:A,A17,SAIDA!C:C) -> 0
A18: 100C37DJ10 | B18: 100C37DJ10 | C18: F 34 | D18: =IF(ISBLANK($D$2),SUMIFS(Entradas!$C:$C,Entradas!$A:$A,$A18)-SUMIFS(SAIDA!$C:$C,SAIDA!$A:$A,$A18),SUMIFS(Entradas!$C:$C,Entradas!$A:$A,$A18,Entradas!$B:$B,"<="&$D$2)-SUMIFS(SAIDA!$C:$C,SAIDA!$A:$A,$A18,SAIDA!$B:$B,"<="&$D$2)) -> 1 | E18: =IF($A18="","",IFERROR(VLOOKUP($A18,Entradas!$A:$D,4,FALSE),"")) -> 0 | F18: ALLEN BRADLEY | I18: #N/A | K18: =SUMIF(Entradas!A:A,A18,Entradas!C:C) -> 1 | L18: =SUMIF(SAIDA!A:A,A18,SAIDA!C:C) -> 0
A19: 100C43D00 | B19: 100C43D00 | C19: F 34 | D19: =IF(ISBLANK($D$2),SUMIFS(Entradas!$C:$C,Entradas!$A:$A,$A19)-SUMIFS(SAIDA!$C:$C,SAIDA!$A:$A,$A19),SUMIFS(Entradas!$C:$C,Entradas!$A:$A,$A19,Entradas!$B:$B,"<="&$D$2)-SUMIFS(SAIDA!$C:$C,SAIDA!$A:$A,$A19,SAIDA!$B:$B,"<="&$D$2)) -> 0 | E19: =IF($A19="","",IFERROR(VLOOKUP($A19,Entradas!$A:$D,4,FALSE),"")) -> 0 | F19: ALLEN BRADLEY | I19: #N/A | K19: =SUMIF(Entradas!A:A,A19,Entradas!C:C) -> 0 | L19: =SUMIF(SAIDA!A:A,A19,SAIDA!C:C) -> 0
A20: 100C72KF00 | B20: 100C72KF00 | C20: F 34 | D20: =IF(ISBLANK($D$2),SUMIFS(Entradas!$C:$C,Entradas!$A:$A,$A20)-SUMIFS(SAIDA!$C:$C,SAIDA!$A:$A,$A20),SUMIFS(Entradas!$C:$C,Entradas!$A:$A,$A20,Entradas!$B:$B,"<="&$D$2)-SUMIFS(SAIDA!$C:$C,SAIDA!$A:$A,$A20,SAIDA!$B:$B,"<="&$D$2)) -> 0 | E20: =IF($A20="","",IFERROR(VLOOKUP($A20,Entradas!$A:$D,4,FALSE),"")) -> 0 | F20: ALLEN BRADLEY | I20: #N/A | K20: =SUMIF(Entradas!A:A,A20,Entradas!C:C) -> 0 | L20: =SUMIF(SAIDA!A:A,A20,SAIDA!C:C) -> 0
A21: 100C85D10 | B21: 100C85D10 | C21: F 34 | D21: =IF(ISBLANK($D$2),SUMIFS(Entradas!$C:$C,Entradas!$A:$A,$A21)-SUMIFS(SAIDA!$C:$C,SAIDA!$A:$A,$A21),SUMIFS(Entradas!$C:$C,Entradas!$A:$A,$A21,Entradas!$B:$B,"<="&$D$2)-SUMIFS(SAIDA!$C:$C,SAIDA!$A:$A,$A21,SAIDA!$B:$B,"<="&$D$2)) -> 0 | E21: =IF($A21="","",IFERROR(VLOOKUP($A21,Entradas!$A:$D,4,FALSE),"")) -> 0 | F21: ALLEN BRADLEY | I21: #N/A | K21: =SUMIF(Entradas!A:A,A21,Entradas!C:C) -> 0 | L21: =SUMIF(SAIDA!A:A,A21,SAIDA!C:C) -> 0
A22: 100C85KB10 | B22: 100C85KB10 | C22: F 31 | D22: =IF(ISBLANK($D$2),SUMIFS(Entradas!$C:$C,Entradas!$A:$A,$A22)-SUMIFS(SAIDA!$C:$C,SAIDA!$A:$A,$A22),SUMIFS(Entradas!$C:$C,Entradas!$A:$A,$A22,Entradas!$B:$B,"<="&$D$2)-SUMIFS(SAIDA!$C:$C,SAIDA!$A:$A,$A22,SAIDA!$B:$B,"<="&$D$2)) -> 3 | E22: =IF($A22="","",IFERROR(VLOOKUP($A22,Entradas!$A:$D,4,FALSE),"")) -> 0 | F22: ALLEN BRADLEY | I22: #N/A | K22: =SUMIF(Entradas!A:A,A22,Entradas!C:C) -> 3 | L22: =SUMIF(SAIDA!A:A,A22,SAIDA!C:C) -> 0
A23: 100D210EA11 | B23: 100D210EA11 | C23: F 35 | D23: =IF(ISBLANK($D$2),SUMIFS(Entradas!$C:$C,Entradas!$A:$A,$A23)-SUMIFS(SAIDA!$C:$C,SAIDA!$A:$A,$A23),SUMIFS(Entradas!$C:$C,Entradas!$A:$A,$A23,Entradas!$B:$B,"<="&$D$2)-SUMIFS(SAIDA!$C:$C,SAIDA!$A:$A,$A23,SAIDA!$B:$B,"<="&$D$2)) -> 1 | E23: =IF($A23="","",IFERROR(VLOOKUP($A23,Entradas!$A:$D,4,FALSE),"")) -> 0 | F23: ALLEN BRADLEY | I23: #N/A | K23: =SUMIF(Entradas!A:A,A23,Entradas!C:C) -> 1 | L23: =SUMIF(SAIDA!A:A,A23,SAIDA!C:C) -> 0
A24: 100D860 | B24: 100D860 | C24: F 34 | D24: =IF(ISBLANK($D$2),SUMIFS(Entradas!$C:$C,Entradas!$A:$A,$A24)-SUMIFS(SAIDA!$C:$C,SAIDA!$A:$A,$A24),SUMIFS(Entradas!$C:$C,Entradas!$A:$A,$A24,Entradas!$B:$B,"<="&$D$2)-SUMIFS(SAIDA!$C:$C,SAIDA!$A:$A,$A24,SAIDA!$B:$B,"<="&$D$2)) -> 0 | E24: =IF($A24="","",IFERROR(VLOOKUP($A24,Entradas!$A:$D,4,FALSE),"")) -> 0 | F24: ALLEN BRADLEY | H24: CAIXA DANIFICADA | I24: #N/A | K24: =SUMIF(Entradas!A:A,A24,Entradas!C:C) -> 0 | L24: =SUMIF(SAIDA!A:A,A24,SAIDA!C:C) -> 0
A25: 100DC110 | B25: 100DC110 | C25: F 34 | D25: =IF(ISBLANK($D$2),SUMIFS(Entradas!$C:$C,Entradas!$A:$A,$A25)-SUMIFS(SAIDA!$C:$C,SAIDA!$A:$A,$A25),SUMIFS(Entradas!$C:$C,Entradas!$A:$A,$A25,Entradas!$B:$B,"<="&$D$2)-SUMIFS(SAIDA!$C:$C,SAIDA!$A:$A,$A25,SAIDA!$B:$B,"<="&$D$2)) -> 1 | E25: =IF($A25="","",IFERROR(VLOOKUP($A25,Entradas!$A:$D,4,FALSE),"")) -> 0 | F25: ALLEN BRADLEY | I25: #N/A | K25: =SUMIF(Entradas!A:A,A25,Entradas!C:C) -> 1 | L25: =SUMIF(SAIDA!A:A,A25,SAIDA!C:C) -> 0
A26: 100DNY41R | B26: 100DNY41R | C26: F 36 | D26: =IF(ISBLANK($D$2),SUMIFS(Entradas!$C:$C,Entradas!$A:$A,$A26)-SUMIFS(SAIDA!$C:$C,SAIDA!$A:$A,$A26),SUMIFS(Entradas!$C:$C,Entradas!$A:$A,$A26,Entradas!$B:$B,"<="&$D$2)-SUMIFS(SAIDA!$C:$C,SAIDA!$A:$A,$A26,SAIDA!$B:$B,"<="&$D$2)) -> 5 | E26: =IF($A26="","",IFERROR(VLOOKUP($A26,Entradas!$A:$D,4,FALSE),"")) -> 0 | F26: ALLEN BRADLEY | I26: #N/A | K26: =SUMIF(Entradas!A:A,A26,Entradas!C:C) -> 5 | L26: =SUMIF(SAIDA!A:A,A26,SAIDA!C:C) -> 0
A27: 100DS111 | B27: 100DS111 | C27: F 34 | D27: =IF(ISBLANK($D$2),SUMIFS(Entradas!$C:$C,Entradas!$A:$A,$A27)-SUMIFS(SAIDA!$C:$C,SAIDA!$A:$A,$A27),SUMIFS(Entradas!$C:$C,Entradas!$A:$A,$A27,Entradas!$B:$B,"<="&$D$2)-SUMIFS(SAIDA!$C:$C,SAIDA!$A:$A,$A27,SAIDA!$B:$B,"<="&$D$2)) -> 1 | E27: =IF($A27="","",IFERROR(VLOOKUP($A27,Entradas!$A:$D,4,FALSE),"")) -> 0 | F27: ALLEN BRADLEY | I27: #N/A | K27: =SUMIF(Entradas!A:A,A27,Entradas!C:C) -> 1 | L27: =SUMIF(SAIDA!A:A,A27,SAIDA!C:C) -> 0
A28: 100DS211 | B28: 100DS211 | C28: F 34 | D28: =IF(ISBLANK($D$2),SUMIFS(Entradas!$C:$C,Entradas!$A:$A,$A28)-SUMIFS(SAIDA!$C:$C,SAIDA!$A:$A,$A28),SUMIFS(Entradas!$C:$C,Entradas!$A:$A,$A28,Entradas!$B:$B,"<="&$D$2)-SUMIFS(SAIDA!$C:$C,SAIDA!$A:$A,$A28,SAIDA!$B:$B,"<="&$D$2)) -> 2 | E28: =IF($A28="","",IFERROR(VLOOKUP($A28,Entradas!$A:$D,4,FALSE),"")) -> 0 | F28: ALLEN BRADLEY | H28: 2 PC-F/CAIXA (LOCALIZADO NA CAIXA 01) | I28: #N/A | K28: =SUMIF(Entradas!A:A,A28,Entradas!C:C) -> 2 | L28: =SUMIF(SAIDA!A:A,A28,SAIDA!C:C) -> 0
A29: 100DTB420 | B29: 100DTB420 | C29: F 35 | D29: =IF(ISBLANK($D$2),SUMIFS(Entradas!$C:$C,Entradas!$A:$A,$A29)-SUMIFS(SAIDA!$C:$C,SAIDA!$A:$A,$A29),SUMIFS(Entradas!$C:$C,Entradas!$A:$A,$A29,Entradas!$B:$B,"<="&$D$2)-SUMIFS(SAIDA!$C:$C,SAIDA!$A:$A,$A29,SAIDA!$B:$B,"<="&$D$2)) -> 1 | E29: =IF($A29="","",IFERROR(VLOOKUP($A29,Entradas!$A:$D,4,FALSE),"")) -> 0 | F29: ALLEN BRADLEY | I29: #N/A | K29: =SUMIF(Entradas!A:A,A29,Entradas!C:C) -> 1 | L29: =SUMIF(SAIDA!A:A,A29,SAIDA!C:C) -> 0
A30: 100-FA11 | B30: 100-FA11 | C30: F 34 | D30: =IF(ISBLANK($D$2),SUMIFS(Entradas!$C:$C,Entradas!$A:$A,$A30)-SUMIFS(SAIDA!$C:$C,SAIDA!$A:$A,$A30),SUMIFS(Entradas!$C:$C,Entradas!$A:$A,$A30,Entradas!$B:$B,"<="&$D$2)-SUMIFS(SAIDA!$C:$C,SAIDA!$A:$A,$A30,SAIDA!$B:$B,"<="&$D$2)) -> 14 | E30: =IF($A30="","",IFERROR(VLOOKUP($A30,Entradas!$A:$D,4,FALSE),"")) -> 0 | F30: ALLEN BRADLEY | I30: #N/A | K30: =SUMIF(Entradas!A:A,A30,Entradas!C:C) -> 14 | L30: =SUMIF(SAIDA!A:A,A30,SAIDA!C:C) -> 0
A31: 100-FA22 | B31: 100-FA22 | C31: F 34 | D31: =IF(ISBLANK($D$2),SUMIFS(Entradas!$C:$C,Entradas!$A:$A,$A31)-SUMIFS(SAIDA!$C:$C,SAIDA!$A:$A,$A31),SUMIFS(Entradas!$C:$C,Entradas!$A:$A,$A31,Entradas!$B:$B,"<="&$D$2)-SUMIFS(SAIDA!$C:$C,SAIDA!$A:$A,$A31,SAIDA!$B:$B,"<="&$D$2)) -> 7 | E31: =IF($A31="","",IFERROR(VLOOKUP($A31,Entradas!$A:$D,4,FALSE),"")) -> 0 | F31: ALLEN BRADLEY | K31: =SUMIF(Entradas!A:A,A31,Entradas!C:C) -> 7 | L31: =SUMIF(SAIDA!A:A,A31,SAIDA!C:C) -> 0
A32: 100FA31 | B32: 100FA31 | C32: F 34 | D32: =IF(ISBLANK($D$2),SUMIFS(Entradas!$C:$C,Entradas!$A:$A,$A32)-SUMIFS(SAIDA!$C:$C,SAIDA!$A:$A,$A32),SUMIFS(Entradas!$C:$C,Entradas!$A:$A,$A32,Entradas!$B:$B,"<="&$D$2)-SUMIFS(SAIDA!$C:$C,SAIDA!$A:$A,$A32,SAIDA!$B:$B,"<="&$D$2)) -> 1 | E32: =IF($A32="","",IFERROR(VLOOKUP($A32,Entradas!$A:$D,4,FALSE),"")) -> 0 | F32: ALLEN BRADLEY | I32: #N/A | K32: =SUMIF(Entradas!A:A,A32,Entradas!C:C) -> 1 | L32: =SUMIF(SAIDA!A:A,A32,SAIDA!C:C) -> 0
A33: 100FA40 | B33: 100FA40 | C33: F 34 | D33: =IF(ISBLANK($D$2),SUMIFS(Entradas!$C:$C,Entradas!$A:$A,$A33)-SUMIFS(SAIDA!$C:$C,SAIDA!$A:$A,$A33),SUMIFS(Entradas!$C:$C,Entradas!$A:$A,$A33,Entradas!$B:$B,"<="&$D$2)-SUMIFS(SAIDA!$C:$C,SAIDA!$A:$A,$A33,SAIDA!$B:$B,"<="&$D$2)) -> 0 | E33: =IF($A33="","",IFERROR(VLOOKUP($A33,Entradas!$A:$D,4,FALSE),"")) -> 0 | F33: ALLEN BRADLEY | I33: #N/A | K33: =SUMIF(Entradas!A:A,A33,Entradas!C:C) -> 0 | L33: =SUMIF(SAIDA!A:A,A33,SAIDA!C:C) -> 0
A34: 100FPTA180 | B34: 100FPTA180 | C34: F 34 | D34: =IF(ISBLANK($D$2),SUMIFS(Entradas!$C:$C,Entradas!$A:$A,$A34)-SUMIFS(SAIDA!$C:$C,SAIDA!$A:$A,$A34),SUMIFS(Entradas!$C:$C,Entradas!$A:$A,$A34,Entradas!$B:$B,"<="&$D$2)-SUMIFS(SAIDA!$C:$C,SAIDA!$A:$A,$A34,SAIDA!$B:$B,"<="&$D$2)) -> 2 | E34: =IF($A34="","",IFERROR(VLOOKUP($A34,Entradas!$A:$D,4,FALSE),"")) -> 0 | F34: ALLEN BRADLEY | I34: #N/A | K34: =SUMIF(Entradas!A:A,A34,Entradas!C:C) -> 2 | L34: =SUMIF(SAIDA!A:A,A34,SAIDA!C:C) -> 0
A35: 100FPTB30 | B35: 100FPTB30 | C35: F 34 | D35: =IF(ISBLANK($D$2),SUMIFS(Entradas!$C:$C,Entradas!$A:$A,$A35)-SUMIFS(SAIDA!$C:$C,SAIDA!$A:$A,$A35),SUMIFS(Entradas!$C:$C,Entradas!$A:$A,$A35,Entradas!$B:$B,"<="&$D$2)-SUMIFS(SAIDA!$C:$C,SAIDA!$A:$A,$A35,SAIDA!$B:$B,"<="&$D$2)) -> 3 | E35: =IF($A35="","",IFERROR(VLOOKUP($A35,Entradas!$A:$D,4,FALSE),"")) -> 0 | F35: ALLEN BRADLEY | I35: #N/A | K35: =SUMIF(Entradas!A:A,A35,Entradas!C:C) -> 3 | L35: =SUMIF(SAIDA!A:A,A35,SAIDA!C:C) -> 0
A36: 100FSV136 | B36: 100FSV136 | C36: F 34 | D36: =IF(ISBLANK($D$2),SUMIFS(Entradas!$C:$C,Entradas!$A:$A,$A36)-SUMIFS(SAIDA!$C:$C,SAIDA!$A:$A,$A36),SUMIFS(Entradas!$C:$C,Entradas!$A:$A,$A36,Entradas!$B:$B,"<="&$D$2)-SUMIFS(SAIDA!$C:$C,SAIDA!$A:$A,$A36,SAIDA!$B:$B,"<="&$D$2)) -> 16 | E36: =IF($A36="","",IFERROR(VLOOKUP($A36,Entradas!$A:$D,4,FALSE),"")) -> 0 | F36: ALLEN BRADLEY | I36: #N/A | K36: =SUMIF(Entradas!A:A,A36,Entradas!C:C) -> 16 | L36: =SUMIF(SAIDA!A:A,A36,SAIDA!C:C) -> 0
A37: 100K05KA10 | B37: 100K05KA10 | C37: F | D37: =IF(ISBLANK($D$2),SUMIFS(Entradas!$C:$C,Entradas!$A:$A,$A37)-SUMIFS(SAIDA!$C:$C,SAIDA!$A:$A,$A37),SUMIFS(Entradas!$C:$C,Entradas!$A:$A,$A37,Entradas!$B:$B,"<="&$D$2)-SUMIFS(SAIDA!$C:$C,SAIDA!$A:$A,$A37,SAIDA!$B:$B,"<="&$D$2)) -> 1 | E37: =IF($A37="","",IFERROR(VLOOKUP($A37,Entradas!$A:$D,4,FALSE),"")) -> 0 | F37: ALLEN BRADLEY | I37: #N/A | K37: =SUMIF(Entradas!A:A,A37,Entradas!C:C) -> 1 | L37: =SUMIF(SAIDA!A:A,A37,SAIDA!C:C) -> 0
A38: 100K05ZJ300 | B38: 100K05ZJ300 | C38: F | D38: =IF(ISBLANK($D$2),SUMIFS(Entradas!$C:$C,Entradas!$A:$A,$A38)-SUMIFS(SAIDA!$C:$C,SAIDA!$A:$A,$A38),SUMIFS(Entradas!$C:$C,Entradas!$A:$A,$A38,Entradas!$B:$B,"<="&$D$2)-SUMIFS(SAIDA!$C:$C,SAIDA!$A:$A,$A38,SAIDA!$B:$B,"<="&$D$2)) -> 6 | E38: =IF($A38="","",IFERROR(VLOOKUP($A38,Entradas!$A:$D,4,FALSE),"")) -> 0 | F38: ALLEN BRADLEY | I38: #N/A | K38: =SUMIF(Entradas!A:A,A38,Entradas!C:C) -> 6 | L38: =SUMIF(SAIDA!A:A,A38,SAIDA!C:C) -> 0
A39: 100K09KF10 | B39: 100K09KF10 | C39: F | D39: =IF(ISBLANK($D$2),SUMIFS(Entradas!$C:$C,Entradas!$A:$A,$A39)-SUMIFS(SAIDA!$C:$C,SAIDA!$A:$A,$A39),SUMIFS(Entradas!$C:$C,Entradas!$A:$A,$A39,Entradas!$B:$B,"<="&$D$2)-SUMIFS(SAIDA!$C:$C,SAIDA!$A:$A,$A39,SAIDA!$B:$B,"<="&$D$2)) -> 9 | E39: =IF($A39="","",IFERROR(VLOOKUP($A39,Entradas!$A:$D,4,FALSE),"")) -> 0 | F39: ALLEN BRADLEY | I39: #N/A | K39: =SUMIF(Entradas!A:A,A39,Entradas!C:C) -> 9 | L39: =SUMIF(SAIDA!A:A,A39,SAIDA!C:C) -> 0
A40: 100KFA13E | B40: 100KFA13E | C40: F 34 | D40: =IF(ISBLANK($D$2),SUMIFS(Entradas!$C:$C,Entradas!$A:$A,$A40)-SUMIFS(SAIDA!$C:$C,SAIDA!$A:$A,$A40),SUMIFS(Entradas!$C:$C,Entradas!$A:$A,$A40,Entradas!$B:$B,"<="&$D$2)-SUMIFS(SAIDA!$C:$C,SAIDA!$A:$A,$A40,SAIDA!$B:$B,"<="&$D$2)) -> 7 | E40: =IF($A40="","",IFERROR(VLOOKUP($A40,Entradas!$A:$D,4,FALSE),"")) -> 0 | F40: ALLEN BRADLEY | H40: F\CX | I40: #N/A | K40: =SUMIF(Entradas!A:A,A40,Entradas!C:C) -> 7 | L40: =SUMIF(SAIDA!A:A,A40,SAIDA!C:C) -> 0
...

Sheet SAIDA
A1: SAIDA DE MATERIAL
A2: CODIGO DO PRODUTO | B2: DATA | C2: QDE.SAIDA | D2: Coluna4 | E2: TOTAL | F2: Coluna6 | G2: Produto | H2: Unidade | I2: DESTINO | J2: ABC | K2: Coluna1
A3: MS132-4.0 | B3: 45110 | C3: 1 | E3: =IF(ISERROR(VLOOKUP(A3,'Controle de Estoque'!A:H,1,FALSE)),"",VLOOKUP(A3,'Controle de Estoque'!A:H,4,FALSE)) -> 5 | J3: =IF(M3<=0.8,"A",IF(M3<=0.95,"B","C")) -> A | K3: =SUMIF($A:$A,A3,$C:$C) -> 7 | L3: =K3/SUM($K$3:$K$847) -> 0.00022906509 | M3: =SUM($L$3:L3) -> 0.00022906509
A4: MS132-6.3 | B4: 45111 | C4: 1 | E4: =IF(ISERROR(VLOOKUP(A4,'Controle de Estoque'!A:H,1,FALSE)),"",VLOOKUP(A4,'Controle de Estoque'!A:H,4,FALSE)) -> 0 | J4: =IF(M4<=0.8,"A",IF(M4<=0.95,"B","C")) -> A | K4: =SUMIF($A:$A,A4,$C:$C) -> 18 | L4: =K4/SUM($K$3:$K$847) -> 0.00058902451 | M4: =SUM($L$3:L4) -> 0.0008180896
A5: ACS-CP-C | B5: 45503 | C5: 27 | E5: =IF(ISERROR(VLOOKUP(A5,'Controle de Estoque'!A:H,1,FALSE)),"",VLOOKUP(A5,'Controle de Estoque'!A:H,4,FALSE)) -> 9 | G5: =IF(ISBLANK(A5),"",IF(ISERROR(VLOOKUP(A5,'Controle de Estoque'!A:I,1,FALSE)),"Produto não cadastrado",VLOOKUP(A5,'Controle de Estoque'!A:I,2,FALSE))) -> ACS-CP-C | H5: =IF(ISERROR(VLOOKUP(A5,'Controle de Estoque'!A:I,1,FALSE)),"",VLOOKUP(A5,'Controle de Estoque'!A:I,3,FALSE)) -> C 02 | J5: =IF(M5<=0.8,"A",IF(M5<=0.95,"B","C")) -> A | K5: =SUMIF($A:$A,A5,$C:$C) -> 73 | L5: =K5/SUM($K$3:$K$847) -> 0.0023888216 | M5: =SUM($L$3:L5) -> 0.0032069112
A6: CP-E24/2.5 | B6: 45602 | C6: 2 | E6: =IF(ISERROR(VLOOKUP(A6,'Controle de Estoque'!A:H,1,FALSE)),"",VLOOKUP(A6,'Controle de Estoque'!A:H,4,FALSE)) -> 1 | G6: =IF(ISBLANK(A6),"",IF(ISERROR(VLOOKUP(A6,'Controle de Estoque'!A:I,1,FALSE)),"Produto não cadastrado",VLOOKUP(A6,'Controle de Estoque'!A:I,2,FALSE))) -> 1SVR427032R0000 | I6: I1079B1068I10I1066:I1096 | J6: =IF(M6<=0.8,"A",IF(M6<=0.95,"B","C")) -> A | K6: =SUMIF($A:$A,A6,$C:$C) -> 15 | L6: =K6/SUM($K$3:$K$847) -> 0.00049085376 | M6: =SUM($L$3:L6) -> 0.003697765
A7: N1673.9PT | B7: 45632 | C7: 36 | E7: =IF(ISERROR(VLOOKUP(A7,'Controle de Estoque'!A:H,1,FALSE)),"",VLOOKUP(A7,'Controle de Estoque'!A:H,4,FALSE)) -> 29 | G7: =IF(ISBLANK(A7),"",IF(ISERROR(VLOOKUP(A7,'Controle de Estoque'!A:I,1,FALSE)),"Produto não cadastrado",VLOOKUP(A7,'Controle de Estoque'!A:I,2,FALSE))) -> 2CLA167390N1804S | H7: =IF(ISERROR(VLOOKUP(A7,'Controle de Estoque'!A:I,1,FALSE)),"",VLOOKUP(A7,'Controle de Estoque'!A:I,3,FALSE)) -> I 10 | J7: =IF(M7<=0.8,"A",IF(M7<=0.95,"B","C")) -> A | K7: =SUMIF($A:$A,A7,$C:$C) -> 75 | L7: =K7/SUM($K$3:$K$847) -> 0.0024542688 | M7: =SUM($L$3:L7) -> 0.0061520338
A8: N1673.9BL | B8: 45632 | C8: 6 | E8: =IF(ISERROR(VLOOKUP(A8,'Controle de Estoque'!A:H,1,FALSE)),"",VLOOKUP(A8,'Controle de Estoque'!A:H,4,FALSE)) -> 0 | G8: =IF(ISBLANK(A8),"",IF(ISERROR(VLOOKUP(A8,'Controle de Estoque'!A:I,1,FALSE)),"Produto não cadastrado",VLOOKUP(A8,'Controle de Estoque'!A:I,2,FALSE))) -> 2CLA167390N1104S | H8: =IF(ISERROR(VLOOKUP(A8,'Controle de Estoque'!A:I,1,FALSE)),"",VLOOKUP(A8,'Controle de Estoque'!A:I,3,FALSE)) -> I 05 | I8: GUSTAVO JORGE | J8: =IF(M8<=0.8,"A",IF(M8<=0.95,"B","C")) -> A | K8: =SUMIF($A:$A,A8,$C:$C) -> 57 | L8: =K8/SUM($K$3:$K$847) -> 0.0018652443 | M8: =SUM($L$3:L8) -> 0.0080172781
A9: N1672.4PT | B9: 45632 | C9: 17 | E9: =IF(ISERROR(VLOOKUP(A9,'Controle de Estoque'!A:H,1,FALSE)),"",VLOOKUP(A9,'Controle de Estoque'!A:H,4,FALSE)) -> 71 | G9: =IF(ISBLANK(A9),"",IF(ISERROR(VLOOKUP(A9,'Controle de Estoque'!A:I,1,FALSE)),"Produto não cadastrado",VLOOKUP(A9,'Controle de Estoque'!A:I,2,FALSE))) -> 2CLA167240N1604S | H9: =IF(ISERROR(VLOOKUP(A9,'Controle de Estoque'!A:I,1,FALSE)),"",VLOOKUP(A9,'Controle de Estoque'!A:I,3,FALSE)) -> I 10 | I9: GUSTAVO JORGE | J9: =IF(M9<=0.8,"A",IF(M9<=0.95,"B","C")) -> A | K9: =SUMIF($A:$A,A9,$C:$C) -> 18 | L9: =K9/SUM($K$3:$K$847) -> 0.00058902451 | M9: =SUM($L$3:L9) -> 0.0086063026
A10: N1672.4BL | B10: 45632 | C10: 1 | E10: =IF(ISERROR(VLOOKUP(A10,'Controle de Estoque'!A:H,1,FALSE)),"",VLOOKUP(A10,'Controle de Estoque'!A:H,4,FALSE)) -> 14 | G10: =IF(ISBLANK(A10),"",IF(ISERROR(VLOOKUP(A10,'Controle de Estoque'!A:I,1,FALSE)),"Produto não cadastrado",VLOOKUP(A10,'Controle de Estoque'!A:I,2,FALSE))) -> 2CLA167240N1104S | H10: =IF(ISERROR(VLOOKUP(A10,'Controle de Estoque'!A:I,1,FALSE)),"",VLOOKUP(A10,'Controle de Estoque'!A:I,3,FALSE)) -> I 05 | I10: GUSTAVO JORGE | J10: =IF(M10<=0.8,"A",IF(M10<=0.95,"B","C")) -> A | K10: =SUMIF($A:$A,A10,$C:$C) -> 16 | L10: =K10/SUM($K$3:$K$847) -> 0.00052357734 | M10: =SUM($L$3:L10) -> 0.0091298799
A11: N1671.1PT | B11: 45632 | C11: 3 | E11: =IF(ISERROR(VLOOKUP(A11,'Controle de Estoque'!A:H,1,FALSE)),"",VLOOKUP(A11,'Controle de Estoque'!A:H,4,FALSE)) -> 36 | G11: =IF(ISBLANK(A11),"",IF(ISERROR(VLOOKUP(A11,'Controle de Estoque'!A:I,1,FALSE)),"Produto não cadastrado",VLOOKUP(A11,'Controle de Estoque'!A:I,2,FALSE))) -> 2CLA167110N1604S | H11: =IF(ISERROR(VLOOKUP(A11,'Controle de Estoque'!A:I,1,FALSE)),"",VLOOKUP(A11,'Controle de Estoque'!A:I,3,FALSE)) -> I 10 | I11: GUSTAVO JORGE | J11: =IF(M11<=0.8,"A",IF(M11<=0.95,"B","C")) -> A | K11: =SUMIF($A:$A,A11,$C:$C) -> 19 | L11: =K11/SUM($K$3:$K$847) -> 0.00062174809 | M11: =SUM($L$3:L11) -> 0.009751628
A12: N1671.1BL | B12: 45632 | C12: 1 | E12: =IF(ISERROR(VLOOKUP(A12,'Controle de Estoque'!A:H,1,FALSE)),"",VLOOKUP(A12,'Controle de Estoque'!A:H,4,FALSE)) -> 4 | G12: =IF(ISBLANK(A12),"",IF(ISERROR(VLOOKUP(A12,'Controle de Estoque'!A:I,1,FALSE)),"Produto não cadastrado",VLOOKUP(A12,'Controle de Estoque'!A:I,2,FALSE))) -> 2CLA167110N1104S | H12: =IF(ISERROR(VLOOKUP(A12,'Controle de Estoque'!A:I,1,FALSE)),"",VLOOKUP(A12,'Controle de Estoque'!A:I,3,FALSE)) -> I 05 | I12: GUSTAVO JORGE | J12: =IF(M12<=0.8,"A",IF(M12<=0.95,"B","C")) -> A | K12: =SUMIF($A:$A,A12,$C:$C) -> 20 | L12: =K12/SUM($K$3:$K$847) -> 0.00065447168 | M12: =SUM($L$3:L12) -> 0.0104061
A13: N1373.9PT | B13: 45632 | C13: 6 | E13: =IF(ISERROR(VLOOKUP(A13,'Controle de Estoque'!A:H,1,FALSE)),"",VLOOKUP(A13,'Controle de Estoque'!A:H,4,FALSE)) -> 131 | G13: =IF(ISBLANK(A13),"",IF(ISERROR(VLOOKUP(A13,'Controle de Estoque'!A:I,1,FALSE)),"Produto não cadastrado",VLOOKUP(A13,'Controle de Estoque'!A:I,2,FALSE))) -> 2CLA137390N1804S | H13: =IF(ISERROR(VLOOKUP(A13,'Controle de Estoque'!A:I,1,FALSE)),"",VLOOKUP(A13,'Controle de Estoque'!A:I,3,FALSE)) -> I 09 | I13: GUSTAVO JORGE | J13: =IF(M13<=0.8,"A",IF(M13<=0.95,"B","C")) -> A | K13: =SUMIF($A:$A,A13,$C:$C) -> 70 | L13: =K13/SUM($K$3:$K$847) -> 0.0022906509 | M13: =SUM($L$3:L13) -> 0.012696751
A14: N1373.9BL | B14: 45632 | C14: 12 | E14: =IF(ISERROR(VLOOKUP(A14,'Controle de Estoque'!A:H,1,FALSE)),"",VLOOKUP(A14,'Controle de Estoque'!A:H,4,FALSE)) -> 0 | G14: =IF(ISBLANK(A14),"",IF(ISERROR(VLOOKUP(A14,'Controle de Estoque'!A:I,1,FALSE)),"Produto não cadastrado",VLOOKUP(A14,'Controle de Estoque'!A:I,2,FALSE))) -> 2CLA137390N1104S | I14: GUSTAVO JORGE | J14: =IF(M14<=0.8,"A",IF(M14<=0.95,"B","C")) -> A | K14: =SUMIF($A:$A,A14,$C:$C) -> 144 | L14: =K14/SUM($K$3:$K$847) -> 0.0047121961 | M14: =SUM($L$3:L14) -> 0.017408947
A15: N1372.2PT | B15: 45632 | C15: 17 | E15: =IF(ISERROR(VLOOKUP(A15,'Controle de Estoque'!A:H,1,FALSE)),"",VLOOKUP(A15,'Controle de Estoque'!A:H,4,FALSE)) -> 153 | G15: =IF(ISBLANK(A15),"",IF(ISERROR(VLOOKUP(A15,'Controle de Estoque'!A:I,1,FALSE)),"Produto não cadastrado",VLOOKUP(A15,'Controle de Estoque'!A:I,2,FALSE))) -> 2CLA137220N1604S | H15: =IF(ISERROR(VLOOKUP(A15,'Controle de Estoque'!A:I,1,FALSE)),"",VLOOKUP(A15,'Controle de Estoque'!A:I,3,FALSE)) -> I 09 | I15: GUSTAVO JORGE | J15: =IF(M15<=0.8,"A",IF(M15<=0.95,"B","C")) -> A | K15: =SUMIF($A:$A,A15,$C:$C) -> 31 | L15: =K15/SUM($K$3:$K$847) -> 0.0010144311 | M15: =SUM($L$3:L15) -> 0.018423378
A16: N1372.2BL | B16: 45632 | C16: 16 | E16: =IF(ISERROR(VLOOKUP(A16,'Controle de Estoque'!A:H,1,FALSE)),"",VLOOKUP(A16,'Controle de Estoque'!A:H,4,FALSE)) -> 133 | G16: =IF(ISBLANK(A16),"",IF(ISERROR(VLOOKUP(A16,'Controle de Estoque'!A:I,1,FALSE)),"Produto não cadastrado",VLOOKUP(A16,'Controle de Estoque'!A:I,2,FALSE))) -> 2CLA137220N1104S | I16: GUSTAVO JORGE | J16: =IF(M16<=0.8,"A",IF(M16<=0.95,"B","C")) -> A | K16: =SUMIF($A:$A,A16,$C:$C) -> 136 | L16: =K16/SUM($K$3:$K$847) -> 0.0044504074 | M16: =SUM($L$3:L16) -> 0.022873785
A17: N1371.1BL | B17: 45632 | C17: 11 | E17: =IF(ISERROR(VLOOKUP(A17,'Controle de Estoque'!A:H,1,FALSE)),"",VLOOKUP(A17,'Controle de Estoque'!A:H,4,FALSE)) -> 113 | G17: =IF(ISBLANK(A17),"",IF(ISERROR(VLOOKUP(A17,'Controle de Estoque'!A:I,1,FALSE)),"Produto não cadastrado",VLOOKUP(A17,'Controle de Estoque'!A:I,2,FALSE))) -> 2CLA137110N1104S | I17: GUSTAVO JORGE | J17: =IF(M17<=0.8,"A",IF(M17<=0.95,"B","C")) -> A | K17: =SUMIF($A:$A,A17,$C:$C) -> 98 | L17: =K17/SUM($K$3:$K$847) -> 0.0032069112 | M17: =SUM($L$3:L17) -> 0.026080696
A18: N1370.1BL | B18: 45632 | C18: 6 | E18: =IF(ISERROR(VLOOKUP(A18,'Controle de Estoque'!A:H,1,FALSE)),"",VLOOKUP(A18,'Controle de Estoque'!A:H,4,FALSE)) -> 29 | G18: =IF(ISBLANK(A18),"",IF(ISERROR(VLOOKUP(A18,'Controle de Estoque'!A:I,1,FALSE)),"Produto não cadastrado",VLOOKUP(A18,'Controle de Estoque'!A:I,2,FALSE))) -> 2CLA137000N1104S | I18: GUSTAVO JORGE | J18: =IF(M18<=0.8,"A",IF(M18<=0.95,"B","C")) -> A | K18: =SUMIF($A:$A,A18,$C:$C) -> 61 | L18: =K18/SUM($K$3:$K$847) -> 0.0019961386 | M18: =SUM($L$3:L18) -> 0.028076835
A19: N1136.NPT | B19: 45632 | C19: 5 | E19: =IF(ISERROR(VLOOKUP(A19,'Controle de Estoque'!A:H,1,FALSE)),"",VLOOKUP(A19,'Controle de Estoque'!A:H,4,FALSE)) -> 16 | G19: =IF(ISBLANK(A19),"",IF(ISERROR(VLOOKUP(A19,'Controle de Estoque'!A:I,1,FALSE)),"Produto não cadastrado",VLOOKUP(A19,'Controle de Estoque'!A:I,2,FALSE))) -> 2CLA113600N1614S | H19: =IF(ISERROR(VLOOKUP(A19,'Controle de Estoque'!A:I,1,FALSE)),"",VLOOKUP(A19,'Controle de Estoque'!A:I,3,FALSE)) -> I 10 | I19: GUSTAVO JORGE | J19: =IF(M19<=0.8,"A",IF(M19<=0.95,"B","C")) -> A | K19: =SUMIF($A:$A,A19,$C:$C) -> 43 | L19: =K19/SUM($K$3:$K$847) -> 0.0014071141 | M19: =SUM($L$3:L19) -> 0.029483949
A20: N1136.N BL | B20: 45632 | C20: 24 | E20: =IF(ISERROR(VLOOKUP(A20,'Controle de Estoque'!A:H,1,FALSE)),"",VLOOKUP(A20,'Controle de Estoque'!A:H,4,FALSE)) | G20: =IF(ISBLANK(A20),"",IF(ISERROR(VLOOKUP(A20,'Controle de Estoque'!A:I,1,FALSE)),"Produto não cadastrado",VLOOKUP(A20,'Controle de Estoque'!A:I,2,FALSE))) -> Produto não cadastrado | H20: =IF(ISERROR(VLOOKUP(A20,'Controle de Estoque'!A:I,1,FALSE)),"",VLOOKUP(A20,'Controle de Estoque'!A:I,3,FALSE)) | I20: GUSTAVO JORGE | J20: =IF(M20<=0.8,"A",IF(M20<=0.95,"B","C")) -> A | K20: =SUMIF($A:$A,A20,$C:$C) -> 24 | L20: =K20/SUM($K$3:$K$847) -> 0.00078536601 | M20: =SUM($L$3:L20) -> 0.030269315
A21: N1136.2VM | B21: 45632 | C21: 9 | E21: =IF(ISERROR(VLOOKUP(A21,'Controle de Estoque'!A:H,1,FALSE)),"",VLOOKUP(A21,'Controle de Estoque'!A:H,4,FALSE)) -> 6 | G21: =IF(ISBLANK(A21),"",IF(ISERROR(VLOOKUP(A21,'Controle de Estoque'!A:I,1,FALSE)),"Produto não cadastrado",VLOOKUP(A21,'Controle de Estoque'!A:I,2,FALSE))) -> 2CLA113620N1704S | H21: =IF(ISERROR(VLOOKUP(A21,'Controle de Estoque'!A:I,1,FALSE)),"",VLOOKUP(A21,'Controle de Estoque'!A:I,3,FALSE)) -> I 21 | I21: GUSTAVO JORGE | J21: =IF(M21<=0.8,"A",IF(M21<=0.95,"B","C")) -> A | K21: =SUMIF($A:$A,A21,$C:$C) -> 83 | L21: =K21/SUM($K$3:$K$847) -> 0.0027160575 | M21: =SUM($L$3:L21) -> 0.032985373
A22: N1136.2NPT | B22: 45632 | C22: 18 | E22: =IF(ISERROR(VLOOKUP(A22,'Controle de Estoque'!A:H,1,FALSE)),"",VLOOKUP(A22,'Controle de Estoque'!A:H,4,FALSE)) -> 0 | G22: =IF(ISBLANK(A22),"",IF(ISERROR(VLOOKUP(A22,'Controle de Estoque'!A:I,1,FALSE)),"Produto não cadastrado",VLOOKUP(A22,'Controle de Estoque'!A:I,2,FALSE))) -> 2CLA113620N1614S | H22: =IF(ISERROR(VLOOKUP(A22,'Controle de Estoque'!A:I,1,FALSE)),"",VLOOKUP(A22,'Controle de Estoque'!A:I,3,FALSE)) -> I 10 | I22: GUSTAVO JORGE | J22: =IF(M22<=0.8,"A",IF(M22<=0.95,"B","C")) -> A | K22: =SUMIF($A:$A,A22,$C:$C) -> 88 | L22: =K22/SUM($K$3:$K$847) -> 0.0028796754 | M22: =SUM($L$3:L22) -> 0.035865048
A23: N1136.2BL | B23: 45632 | C23: 9 | E23: =IF(ISERROR(VLOOKUP(A23,'Controle de Estoque'!A:H,1,FALSE)),"",VLOOKUP(A23,'Controle de Estoque'!A:H,4,FALSE)) -> 52 | G23: =IF(ISBLANK(A23),"",IF(ISERROR(VLOOKUP(A23,'Controle de Estoque'!A:I,1,FALSE)),"Produto não cadastrado",VLOOKUP(A23,'Controle de Estoque'!A:I,2,FALSE))) -> 2CLA113620N1104S | H23: =IF(ISERROR(VLOOKUP(A23,'Controle de Estoque'!A:I,1,FALSE)),"",VLOOKUP(A23,'Controle de Estoque'!A:I,3,FALSE)) -> I 03 | I23: GUSTAVO JORGE | J23: =IF(M23<=0.8,"A",IF(M23<=0.95,"B","C")) -> A | K23: =SUMIF($A:$A,A23,$C:$C) -> 94 | L23: =K23/SUM($K$3:$K$847) -> 0.0030760169 | M23: =SUM($L$3:L23) -> 0.038941065
A24: N1118.6PT | B24: 45632 | C24: 3 | E24: =IF(ISERROR(VLOOKUP(A24,'Controle de Estoque'!A:H,1,FALSE)),"",VLOOKUP(A24,'Controle de Estoque'!A:H,4,FALSE)) -> 7 | G24: =IF(ISBLANK(A24),"",IF(ISERROR(VLOOKUP(A24,'Controle de Estoque'!A:I,1,FALSE)),"Produto não cadastrado",VLOOKUP(A24,'Controle de Estoque'!A:I,2,FALSE))) -> 2CLA111860N1604S | H24: =IF(ISERROR(VLOOKUP(A24,'Controle de Estoque'!A:I,1,FALSE)),"",VLOOKUP(A24,'Controle de Estoque'!A:I,3,FALSE)) -> I 08 | I24: GUSTAVO JORGE | J24: =IF(M24<=0.8,"A",IF(M24<=0.95,"B","C")) -> A | K24: =SUMIF($A:$A,A24,$C:$C) -> 3 | L24: =K24/SUM($K$3:$K$847) -> 9.8170752e-05 | M24: =SUM($L$3:L24) -> 0.039039236
A25: N1110PT | B25: 45632 | C25: 5 | E25: =IF(ISERROR(VLOOKUP(A25,'Controle de Estoque'!A:H,1,FALSE)),"",VLOOKUP(A25,'Controle de Estoque'!A:H,4,FALSE)) -> 22 | G25: =IF(ISBLANK(A25),"",IF(ISERROR(VLOOKUP(A25,'Controle de Estoque'!A:I,1,FALSE)),"Produto não cadastrado",VLOOKUP(A25,'Controle de Estoque'!A:I,2,FALSE))) -> 2CLA111000N1604S | H25: =IF(ISERROR(VLOOKUP(A25,'Controle de Estoque'!A:I,1,FALSE)),"",VLOOKUP(A25,'Controle de Estoque'!A:I,3,FALSE)) -> I 08 | I25: GUSTAVO JORGE | J25: =IF(M25<=0.8,"A",IF(M25<=0.95,"B","C")) -> A | K25: =SUMIF($A:$A,A25,$C:$C) -> 24 | L25: =K25/SUM($K$3:$K$847) -> 0.00078536601 | M25: =SUM($L$3:L25) -> 0.039824602
A26: N1110BL | B26: 45632 | C26: 4 | E26: =IF(ISERROR(VLOOKUP(A26,'Controle de Estoque'!A:H,1,FALSE)),"",VLOOKUP(A26,'Controle de Estoque'!A:H,4,FALSE)) -> 11 | G26: =IF(ISBLANK(A26),"",IF(ISERROR(VLOOKUP(A26,'Controle de Estoque'!A:I,1,FALSE)),"Produto não cadastrado",VLOOKUP(A26,'Controle de Estoque'!A:I,2,FALSE))) -> 2CLA111000N1104S | H26: =IF(ISERROR(VLOOKUP(A26,'Controle de Estoque'!A:I,1,FALSE)),"",VLOOKUP(A26,'Controle de Estoque'!A:I,3,FALSE)) -> I 02 | I26: GUSTAVO JORGE | J26: =IF(M26<=0.8,"A",IF(M26<=0.95,"B","C")) -> A | K26: =SUMIF($A:$A,A26,$C:$C) -> 27 | L26: =K26/SUM($K$3:$K$847) -> 0.00088353676 | M26: =SUM($L$3:L26) -> 0.040708138
A27: N1102PT | B27: 45632 | C27: 4 | E27: =IF(ISERROR(VLOOKUP(A27,'Controle de Estoque'!A:H,1,FALSE)),"",VLOOKUP(A27,'Controle de Estoque'!A:H,4,FALSE)) -> 111 | G27: =IF(ISBLANK(A27),"",IF(ISERROR(VLOOKUP(A27,'Controle de Estoque'!A:I,1,FALSE)),"Produto não cadastrado",VLOOKUP(A27,'Controle de Estoque'!A:I,2,FALSE))) -> 2CLA110210N1604S | H27: =IF(ISERROR(VLOOKUP(A27,'Controle de Estoque'!A:I,1,FALSE)),"",VLOOKUP(A27,'Controle de Estoque'!A:I,3,FALSE)) -> I 08 | I27: GUSTAVO JORGE | J27: =IF(M27<=0.8,"A",IF(M27<=0.95,"B","C")) -> A | K27: =SUMIF($A:$A,A27,$C:$C) -> 22 | L27: =K27/SUM($K$3:$K$847) -> 0.00071991885 | M27: =SUM($L$3:L27) -> 0.041428057
A28: N1102BL | B28: 45632 | C28: 16 | E28: =IF(ISERROR(VLOOKUP(A28,'Controle de Estoque'!A:H,1,FALSE)),"",VLOOKUP(A28,'Controle de Estoque'!A:H,4,FALSE)) -> 67 | G28: =IF(ISBLANK(A28),"",IF(ISERROR(VLOOKUP(A28,'Controle de Estoque'!A:I,1,FALSE)),"Produto não cadastrado",VLOOKUP(A28,'Controle de Estoque'!A:I,2,FALSE))) -> 2CLA110210N1104S | H28: =IF(ISERROR(VLOOKUP(A28,'Controle de Estoque'!A:I,1,FALSE)),"",VLOOKUP(A28,'Controle de Estoque'!A:I,3,FALSE)) -> I 02 | I28: GUSTAVO JORGE | J28: =IF(M28<=0.8,"A",IF(M28<=0.95,"B","C")) -> A | K28: =SUMIF($A:$A,A28,$C:$C) -> 99 | L28: =K28/SUM($K$3:$K$847) -> 0.0032396348 | M28: =SUM($L$3:L28) -> 0.044667692
A29: N1101PT | B29: 45632 | C29: 5 | E29: =IF(ISERROR(VLOOKUP(A29,'Controle de Estoque'!A:H,1,FALSE)),"",VLOOKUP(A29,'Controle de Estoque'!A:H,4,FALSE)) -> 156 | G29: =IF(ISBLANK(A29),"",IF(ISERROR(VLOOKUP(A29,'Controle de Estoque'!A:I,1,FALSE)),"Produto não cadastrado",VLOOKUP(A29,'Controle de Estoque'!A:I,2,FALSE))) -> 2CLA110100N1604S | H29: =IF(ISERROR(VLOOKUP(A29,'Controle de Estoque'!A:I,1,FALSE)),"",VLOOKUP(A29,'Controle de Estoque'!A:I,3,FALSE)) -> I 08 | I29: GUSTAVO JORGE | J29: =IF(M29<=0.8,"A",IF(M29<=0.95,"B","C")) -> A | K29: =SUMIF($A:$A,A29,$C:$C) -> 15 | L29: =K29/SUM($K$3:$K$847) -> 0.00049085376 | M29: =SUM($L$3:L29) -> 0.045158546
A30: N1101BL | B30: 45632 | C30: 8 | E30: =IF(ISERROR(VLOOKUP(A30,'Controle de Estoque'!A:H,1,FALSE)),"",VLOOKUP(A30,'Controle de Estoque'!A:H,4,FALSE)) -> 476 | G30: =IF(ISBLANK(A30),"",IF(ISERROR(VLOOKUP(A30,'Controle de Estoque'!A:I,1,FALSE)),"Produto não cadastrado",VLOOKUP(A30,'Controle de Estoque'!A:I,2,FALSE))) -> 2CLA110100N1104S | I30: GUSTAVO JORGE | J30: =IF(M30<=0.8,"A",IF(M30<=0.95,"B","C")) -> A | K30: =SUMIF($A:$A,A30,$C:$C) -> 117 | L30: =K30/SUM($K$3:$K$847) -> 0.0038286593 | M30: =SUM($L$3:L30) -> 0.048987205
A31: N1100PT | B31: 45632 | C31: 5 | E31: =IF(ISERROR(VLOOKUP(A31,'Controle de Estoque'!A:H,1,FALSE)),"",VLOOKUP(A31,'Controle de Estoque'!A:H,4,FALSE)) -> 108 | G31: =IF(ISBLANK(A31),"",IF(ISERROR(VLOOKUP(A31,'Controle de Estoque'!A:I,1,FALSE)),"Produto não cadastrado",VLOOKUP(A31,'Controle de Estoque'!A:I,2,FALSE))) -> 2CLA110000N1604S | H31: =IF(ISERROR(VLOOKUP(A31,'Controle de Estoque'!A:I,1,FALSE)),"",VLOOKUP(A31,'Controle de Estoque'!A:I,3,FALSE)) -> I 08 | I31: GUSTAVO JORGE | J31: =IF(M31<=0.8,"A",IF(M31<=0.95,"B","C")) -> A | K31: =SUMIF($A:$A,A31,$C:$C) -> 19 | L31: =K31/SUM($K$3:$K$847) -> 0.00062174809 | M31: =SUM($L$3:L31) -> 0.049608953
A32: MS116-6.3 | B32: 45632 | C32: 1 | E32: =IF(ISERROR(VLOOKUP(A32,'Controle de Estoque'!A:H,1,FALSE)),"",VLOOKUP(A32,'Controle de Estoque'!A:H,4,FALSE)) -> 2 | G32: =IF(ISBLANK(A32),"",IF(ISERROR(VLOOKUP(A32,'Controle de Estoque'!A:I,1,FALSE)),"Produto não cadastrado",VLOOKUP(A32,'Controle de Estoque'!A:I,2,FALSE))) -> 1SAM250000R1009 | H32: =IF(ISERROR(VLOOKUP(A32,'Controle de Estoque'!A:I,1,FALSE)),"",VLOOKUP(A32,'Controle de Estoque'!A:I,3,FALSE)) -> C 08 | I32: GUSTAVO JORGE | J32: =IF(M32<=0.8,"A",IF(M32<=0.95,"B","C")) -> A | K32: =SUMIF($A:$A,A32,$C:$C) -> 10 | L32: =K32/SUM($K$3:$K$847) -> 0.00032723584 | M32: =SUM($L$3:L32) -> 0.049936189
A33: MS116-4.0 | B33: 45632 | C33: 2 | E33: =IF(ISERROR(VLOOKUP(A33,'Controle de Estoque'!A:H,1,FALSE)),"",VLOOKUP(A33,'Controle de Estoque'!A:H,4,FALSE)) -> 3 | G33: =IF(ISBLANK(A33),"",IF(ISERROR(VLOOKUP(A33,'Controle de Estoque'!A:I,1,FALSE)),"Produto não cadastrado",VLOOKUP(A33,'Controle de Estoque'!A:I,2,FALSE))) -> 1SAM250000R1008 | H33: =IF(ISERROR(VLOOKUP(A33,'Controle de Estoque'!A:I,1,FALSE)),"",VLOOKUP(A33,'Controle de Estoque'!A:I,3,FALSE)) -> C 08 | I33: GUSTAVO JORGE | J33: =IF(M33<=0.8,"A",IF(M33<=0.95,"B","C")) -> A | K33: =SUMIF($A:$A,A33,$C:$C) -> 12 | L33: =K33/SUM($K$3:$K$847) -> 0.00039268301 | M33: =SUM($L$3:L33) -> 0.050328872
A34: MS116-12 | B34: 45632 | C34: 1 | E34: =IF(ISERROR(VLOOKUP(A34,'Controle de Estoque'!A:H,1,FALSE)),"",VLOOKUP(A34,'Controle de Estoque'!A:H,4,FALSE)) -> 7 | G34: =IF(ISBLANK(A34),"",IF(ISERROR(VLOOKUP(A34,'Controle de Estoque'!A:I,1,FALSE)),"Produto não cadastrado",VLOOKUP(A34,'Controle de Estoque'!A:I,2,FALSE))) -> 1SAM250000R1012 | H34: =IF(ISERROR(VLOOKUP(A34,'Controle de Estoque'!A:I,1,FALSE)),"",VLOOKUP(A34,'Controle de Estoque'!A:I,3,FALSE)) -> C 08 | I34: GUSTAVO JORGE | J34: =IF(M34<=0.8,"A",IF(M34<=0.95,"B","C")) -> A | K34: =SUMIF($A:$A,A34,$C:$C) -> 3 | L34: =K34/SUM($K$3:$K$847) -> 9.8170752e-05 | M34: =SUM($L$3:L34) -> 0.050427043
A35: AX12-30-10-75 | B35: 45632 | C35: 1 | E35: =IF(ISERROR(VLOOKUP(A35,'Controle de Estoque'!A:H,1,FALSE)),"",VLOOKUP(A35,'Controle de Estoque'!A:H,4,FALSE)) -> 4 | G35: =IF(ISBLANK(A35),"",IF(ISERROR(VLOOKUP(A35,'Controle de Estoque'!A:I,1,FALSE)),"Produto não cadastrado",VLOOKUP(A35,'Controle de Estoque'!A:I,2,FALSE))) -> 1SBL911074R7510 | H35: =IF(ISERROR(VLOOKUP(A35,'Controle de Estoque'!A:I,1,FALSE)),"",VLOOKUP(A35,'Controle de Estoque'!A:I,3,FALSE)) -> C 02 | I35: GUSTAVO JORGE | J35: =IF(M35<=0.8,"A",IF(M35<=0.95,"B","C")) -> A | K35: =SUMIF($A:$A,A35,$C:$C) -> 11 | L35: =K35/SUM($K$3:$K$847) -> 0.00035995942 | M35: =SUM($L$3:L35) -> 0.050787002
A36: AX09-30-10-75 | B36: 45632 | C36: 3 | E36: =IF(ISERROR(VLOOKUP(A36,'Controle de Estoque'!A:H,1,FALSE)),"",VLOOKUP(A36,'Controle de Estoque'!A:H,4,FALSE)) -> 0 | G36: =IF(ISBLANK(A36),"",IF(ISERROR(VLOOKUP(A36,'Controle de Estoque'!A:I,1,FALSE)),"Produto não cadastrado",VLOOKUP(A36,'Controle de Estoque'!A:I,2,FALSE))) -> 1SBL901074R7510 | H36: =IF(ISERROR(VLOOKUP(A36,'Controle de Estoque'!A:I,1,FALSE)),"",VLOOKUP(A36,'Controle de Estoque'!A:I,3,FALSE)) -> C 09 | I36: GUSTAVO JORGE | J36: =IF(M36<=0.8,"A",IF(M36<=0.95,"B","C")) -> A | K36: =SUMIF($A:$A,A36,$C:$C) -> 22 | L36: =K36/SUM($K$3:$K$847) -> 0.00071991885 | M36: =SUM($L$3:L36) -> 0.051506921
A37: ZMU-03 | B37: 45632 | C37: 1 | E37: =IF(ISERROR(VLOOKUP(A37,'Controle de Estoque'!A:H,1,FALSE)),"",VLOOKUP(A37,'Controle de Estoque'!A:H,4,FALSE)) -> 1 | G37: =IF(ISBLANK(A37),"",IF(ISERROR(VLOOKUP(A37,'Controle de Estoque'!A:I,1,FALSE)),"Produto não cadastrado",VLOOKUP(A37,'Controle de Estoque'!A:I,2,FALSE))) -> 3AXD50000223107A | H37: =IF(ISERROR(VLOOKUP(A37,'Controle de Estoque'!A:I,1,FALSE)),"",VLOOKUP(A37,'Controle de Estoque'!A:I,3,FALSE)) -> ARMARIO 01 | I37: MASTER KIT | J37: =IF(M37<=0.8,"A",IF(M37<=0.95,"B","C")) -> A | K37: =SUMIF($A:$A,A37,$C:$C) -> 3 | L37: =K37/SUM($K$3:$K$847) -> 9.8170752e-05 | M37: =SUM($L$3:L37) -> 0.051605092
